Workbook

Sheet Souhrn-HS
A1: SOUHRN HS KÓDŮ / HS CODE SUMMARY
A3: Klient / Client | B3: MOREK CZ s.r.o., Kubelíkova 1224/42, 130 00 Praha, CZ (VAT CZ03088316)
A4: Odesílatel / Sender | B4: Guangdong Grandview Technology Co., Ltd, Dongguan, Guangdong, China
A5: Zásilka / Shipment (B/L) | B5: F202615259 — HMM DUBLIN 019W, Yantian → Hamburg → CZ
A6: Faktury / Invoices | B6: CI-26051504 a CI-26051902, obě ze dne 02.06.2026
A7: Kontejnery / Containers | B7: 2 × 40'HQ: TGBU9796804 (23 plt / 415 ktn), TLLU5520254 (19 plt / 314 ktn)
A8: Země původu / Country of origin | B8: Čína / China (CN)
A9: Incoterm | B9: EXW — named place NEUVEDENO na fakturách (viz Poznámky, bod 2)
A10: Měna / Currency | B10: USD
A11: Sleva / Discount | B11: Žádná — fakturovaná částka = součet položek (no discount to apportion)
A12: Datum zpracování | B12: 4. 8. 2026
A14: Odesílatel / Sender | B14: HS kód (CN) | C14: Popis zboží (CZ) | D14: Description (EN) | E14: Čistá hm. / Net (kg) | F14: Hrubá hm. / Gross (kg) | G14: Množství / Qty | H14: MJ / Unit | I14: Celní hodnota / Customs value (USD) | J14: CBAM | K14: Antidumping
A15: Guangdong Grandview Technology Co., Ltd, Dongguan, Guangdong, China | B15: 8547 20 00 | C15: Smršťovací izolační trubice a bužírky z plastů a sady z nich (tenkostěnné, středněstěnné a silnostěnné, s lepidlem i bez, a sady MSTS pro kabelové spojky/koncovky) | D15: Heat-shrinkable plastic insulating tubing/sleeving and kits thereof (thinwall, mediumwall, heavywall, with and without adhesive liner, and MSTS cable jointing/termination kits) | E15: =SUMIFS('Rozpad-dle-produktu'!$I$10:$I$18,'Rozpad-dle-produktu'!$C$10:$C$18,"TW")+SUMIFS('Rozpad-dle-produktu'!$I$10:$I$18,'Rozpad-dle-produktu'!$C$10:$C$18,"MW-A")+SUMIFS('Rozpad-dle-produktu'!$I$10:$I$18,'Rozpad-dle-produktu'!$C$10:$C$18,"MW-U")+SUMIFS('Rozpad-dle-produktu'!$I$10:$I$18,'Rozpad-dle-produktu'!$C$10:$C$18,"HW")+SUMIFS('Rozpad-dle-produktu'!$I$10:$I$18,'Rozpad-dle-produktu'!$C$10:$C$18,"KIT") -> 9643 | F15: =SUMIFS('Rozpad-dle-produktu'!$J$10:$J$18,'Rozpad-dle-produktu'!$C$10:$C$18,"TW")+SUMIFS('Rozpad-dle-produktu'!$J$10:$J$18,'Rozpad-dle-produktu'!$C$10:$C$18,"MW-A")+SUMIFS('Rozpad-dle-produktu'!$J$10:$J$18,'Rozpad-dle-produktu'!$C$10:$C$18,"MW-U")+SUMIFS('Rozpad-dle-produktu'!$J$10:$J$18,'Rozpad-dle-produktu'!$C$10:$C$18,"HW")+SUMIFS('Rozpad-dle-produktu'!$J$10:$J$18,'Rozpad-dle-produktu'!$C$10:$C$18,"KIT") -> 11430 | G15: =SUMIFS('Rozpad-dle-produktu'!$G$10:$G$18,'Rozpad-dle-produktu'!$C$10:$C$18,"TW")+SUMIFS('Rozpad-dle-produktu'!$G$10:$G$18,'Rozpad-dle-produktu'!$C$10:$C$18,"MW-A")+SUMIFS('Rozpad-dle-produktu'!$G$10:$G$18,'Rozpad-dle-produktu'!$C$10:$C$18,"MW-U")+SUMIFS('Rozpad-dle-produktu'!$G$10:$G$18,'Rozpad-dle-produktu'!$C$10:$C$18,"HW")+SUMIFS('Rozpad-dle-produktu'!$G$10:$G$18,'Rozpad-dle-produktu'!$C$10:$C$18,"KIT") -> 135205 | H15: ks / m / sada | I15: =SUMIFS('Rozpad-dle-produktu'!$K$10:$K$18,'Rozpad-dle-produktu'!$C$10:$C$18,"TW")+SUMIFS('Rozpad-dle-produktu'!$K$10:$K$18,'Rozpad-dle-produktu'!$C$10:$C$18,"MW-A")+SUMIFS('Rozpad-dle-produktu'!$K$10:$K$18,'Rozpad-dle-produktu'!$C$10:$C$18,"MW-U")+SUMIFS('Rozpad-dle-produktu'!$K$10:$K$18,'Rozpad-dle-produktu'!$C$10:$C$18,"HW")+SUMIFS('Rozpad-dle-produktu'!$K$10:$K$18,'Rozpad-dle-produktu'!$C$10:$C$18,"KIT") -> 66943.32 | J15: Ne / No | K15: Ne / No — žádné opatření nezjištěno
A16: Guangdong Grandview Technology Co., Ltd, Dongguan, Guangdong, China | B16: k určení / TBC | C16: Tiskové (značkovací) kolečko — zboží nespecifikováno, nutno doplnit | D16: Type wheel (printing/marking wheel) — not specified, needs identification | E16: =SUMIFS('Rozpad-dle-produktu'!$I$10:$I$18,'Rozpad-dle-produktu'!$C$10:$C$18,"OTH") -> 0 | F16: =SUMIFS('Rozpad-dle-produktu'!$J$10:$J$18,'Rozpad-dle-produktu'!$C$10:$C$18,"OTH") -> 0 | G16: =SUMIFS('Rozpad-dle-produktu'!$G$10:$G$18,'Rozpad-dle-produktu'!$C$10:$C$18,"OTH") -> 3 | H16: ks / pcs | I16: =SUMIFS('Rozpad-dle-produktu'!$K$10:$K$18,'Rozpad-dle-produktu'!$C$10:$C$18,"OTH") -> 120 | J16: Ne / No | K16: Ne / No
D17: CELKEM / TOTAL | E17: =SUM(E15:E16) -> 9643 | F17: =SUM(F15:F16) -> 11430 | G17: =SUM(G15:G16) -> 135208 | I17: =SUM(I15:I16) -> 67063.32
A19: Kontrola / Reconciliation
A20: Hrubá hmotnost vs B/L F202615259 | E20: =F17 -> 11430 | F20: 11430 | G20: =IF(ROUND(E20-F20,2)=0,"OK","ROZDÍL / DIFF") -> OK
A21: Čistá hmotnost vs balicí listy PL-504 + PL-902 | E21: =E17 -> 9643 | F21: 9643 | G21: =IF(ROUND(E21-F21,2)=0,"OK","ROZDÍL / DIFF") -> OK
A22: Celní hodnota vs faktury CI-26051504 + CI-26051902 | E22: =I17 -> 67063.32 | F22: 67063.32 | G22: =IF(ROUND(E22-F22,2)=0,"OK","ROZDÍL / DIFF") -> OK
A23: Modrá = hodnota převzatá z dokladu; černá = vypočteno vzorcem.

Sheet Polozky-faktury
A1: Konsignace / Consignment | B1: Řádek / Line | C1: Customer PN | D1: Skupina / Group | E1: Popis / Description | F1: Rozměr / Spec | G1: Množství / Qty | H1: MJ / Unit | I1: Jedn. cena / Unit price (USD) | J1: Hodnota / Value (USD)
A2: CI-26051504 | B2: 1 | C2: MSTS2403A037 | D2: KIT | E2: MSTS cable jointing/termination kits (sets of heat-shrink tubes) | F2: PO: 3x MW45/12- 250mm+1xHW115/34- 900 mm PO: | G2: 630 | H2: kit | I2: 5.22 | J2: 3288.6
A3: CI-26051504 | B3: 2 | C3: MHWT00903A10 | D3: HW | E3: Heavywall heat-shrink tubing with adhesive (GHWT) | F3: HW 9/3- 1000mm | G3: 440 | H3: pcs | I3: 0.447 | J3: 196.68
A4: CI-26051504 | B4: 3 | C4: MHWT01605A10 | D4: HW | E4: Heavywall heat-shrink tubing with adhesive (GHWT) | F4: HW16/5- 1000mm | G4: 100 | H4: pcs | I4: 0.589 | J4: 58.9
A5: CI-26051504 | B5: 4 | C5: MHWT01905A10 | D5: HW | E5: Heavywall heat-shrink tubing with adhesive (GHWT) | F5: HW19/5- 1000mm | G5: 50 | H5: pcs | I5: 0.656 | J5: 32.8
A6: CI-26051504 | B6: 5 | C6: MHWT03308A10 | D6: HW | E6: Heavywall heat-shrink tubing with adhesive (GHWT) | F6: HW 33/8- 1000mm | G6: 2000 | H6: pcs | I6: 0.922 | J6: 1844
A7: CI-26051504 | B7: 6 | C7: MHWT05516A10 | D7: HW | E7: Heavywall heat-shrink tubing with adhesive (GHWT) | F7: HW 55/16- 1000mm | G7: 50 | H7: pcs | I7: 1.615 | J7: 80.75
A8: CI-26051504 | B8: 7 | C8: MHWT07522A10 | D8: HW | E8: Heavywall heat-shrink tubing with adhesive (GHWT) | F8: HW 75/22- 1000mm | G8: 50 | H8: pcs | I8: 2.233 | J8: 111.65
A9: CI-26051504 | B9: 8 | C9: MMWT01905A10 | D9: MW-A | E9: Mediumwall heat-shrink tubing with adhesive (GMWT) | F9: MW 19/5- 1000mm | G9: 1000 | H9: pcs | I9: 0.608 | J9: 608
A10: CI-26051504 | B10: 9 | C10: MMWT09525A10 | D10: MW-A | E10: Mediumwall heat-shrink tubing with adhesive (GMWT) | F10: MW 95/25- 1000mm | G10: 150 | H10: pcs | I10: 2.394 | J10: 359.1
A11: CI-26051504 | B11: 10 | C11: MMWT00802A10 | D11: MW-A | E11: Mediumwall heat-shrink tubing with adhesive (GMWT) | F11: MW 8/2- 1000mm | G11: 200 | H11: pcs | I11: 0.295 | J11: 59
A12: CI-26051504 | B12: 11 | C12: MMWT07522A10 | D12: MW-A | E12: Mediumwall heat-shrink tubing with adhesive (GMWT) | F12: MW 75/22- 1000mm | G12: 215 | H12: pcs | I12: 1.976 | J12: 424.84
A13: CI-26051504 | B13: 12 | C13: MSTS0162A037 | D13: KIT | E13: MSTS cable jointing/termination kits (sets of heat-shrink tubes) | F13: 4xMW12/3-80mm+1xHW33/8- 330mm 4xMW 45/12-250mm+1HW | G13: 1050 | H13: kit | I13: 0.688 | J13: 722.4
... A34: CI-26051504 | B34: 33 | C34: MTWA12764G10 | D34: TW | E34: Thinwall heat-shrink tubing 2:1, no adhesive (GTW / GTF) | F34: 1000mm | G34: 700 | H34: m | I34: 0.168 | J34: 117.6
A35: CI-26051504 | B35: 34 | C35: MTWA12764R10 | D35: TW | E35: Thinwall heat-shrink tubing 2:1, no adhesive (GTW / GTF) | G35: 700 | H35: m | I35: 0.168 | J35: 117.6
A36: CI-26051504 | B36: 35 | C36: MTWA19095G10 | D36: TW | E36: Thinwall heat-shrink tubing 2:1, no adhesive (GTW / GTF) | G36: 700 | H36: m | I36: 0.359 | J36: 251.3
A37: CI-26051504 | B37: 36 | C37: MTWA19095N10 | D37: TW | E37: Thinwall heat-shrink tubing 2:1, no adhesive (GTW / GTF) | G37: 200 | H37: m | I37: 0.359 | J37: 71.8
A38: CI-26051504 | B38: 37 | C38: MTWA19095R10 | D38: TW | E38: Thinwall heat-shrink tubing 2:1, no adhesive (GTW / GTF) | G38: 700 | H38: m | I38: 0.359 | J38: 251.3
A39: CI-26051504 | B39: 38 | C39: MTWA19095X10 | D39: TW | E39: Thinwall heat-shrink tubing 2:1, no adhesive (GTW / GTF) | G39: 300 | H39: m | I39: 0.302 | J39: 90.6
A40: CI-26051504 | B40: 39 | C40: MTWA38119G10 | D40: TW | E40: Thinwall heat-shrink tubing 2:1, no adhesive (GTW / GTF) | G40: 350 | H40: m | I40: 0.654 | J40: 228.9
A41: CI-26051504 | B41: 40 | C41: MTWA38119R10 | D41: TW | E41: Thinwall heat-shrink tubing 2:1, no adhesive (GTW / GTF) | G41: 350 | H41: m | I41: 0.654 | J41: 228.9
A42: CI-26051504 | B42: 41 | C42: MTWA38119X10 | D42: TW | E42: Thinwall heat-shrink tubing 2:1, no adhesive (GTW / GTF) | G42: 250 | H42: m | I42: 0.956 | J42: 239
A43: CI-26051504 | B43: 42 | C43: MTWA01608B11 | D43: TW | E43: Thinwall heat-shrink tubing 2:1, no adhesive (GTW / GTF) | G43: 5000 | H43: pcs | I43: 0.032 | J43: 160
A44: CI-26051504 | B44: 43 | C44: MTWA01608N11 | D44: TW | E44: Thinwall heat-shrink tubing 2:1, no adhesive (GTW / GTF) | F44: MTWA12764B11 | G44: 400 | H44: pcs | I44: 0.032 | J44: 12.8
A45: CI-26051504 | B45: 44 | C45: MTWA12764B11 | D45: TW | E45: Thinwall heat-shrink tubing 2:1, no adhesive (GTW / GTF) | F45: 12.7/6.4 | G45: 5000 | H45: pcs | I45: 0.158 | J45: 790
A46: CI-26051504 | B46: 45 | C46: MTWA12764X11 | D46: TW | E46: Thinwall heat-shrink tubing 2:1, no adhesive (GTW / GTF) | F46: 12.7/6.4 | G46: 2600 | H46: pcs | I46: 0.179 | J46: 465.4
A47: CI-26051504 | B47: 46 | C47: MTWA16080B11 | D47: TW | E47: Thinwall heat-shrink tubing 2:1, no adhesive (GTW / GTF) | F47: 16.0/8.0 | G47: 1300 | H47: pcs | I47: 0.21 | J47: 273
A48: CI-26051504 | B48: 47 | C48: MTWA16080N11 | D48: TW | E48: Thinwall heat-shrink tubing 2:1, no adhesive (GTW / GTF) | F48: 16.0/8.0 | G48: 280 | H48: pcs | I48: 0.231 | J48: 64.68
A49: CI-26051504 | B49: 48 | C49: MTWA19095N11 | D49: TW | E49: Thinwall heat-shrink tubing 2:1, no adhesive (GTW / GTF) | F49: 19.0/9.5 | G49: 2600 | H49: pcs | I49: 0.378 | J49: 982.8
A50: CI-26051504 | B50: 49 | C50: MTWA19095X11 | D50: TW | E50: Thinwall heat-shrink tubing 2:1, no adhesive (GTW / GTF) | F50: 19.0/9.5 | G50: 1800 | H50: pcs | I50: 0.315 | J50: 567
A51: CI-26051504 | B51: 50 | C51: MTWA02412B11 | D51: TW | E51: Thinwall heat-shrink tubing 2:1, no adhesive (GTW / GTF) | F51: 19.0/9.5 | G51: 3800 | H51: pcs | I51: 0.04 | J51: 152
A52: CI-26051504 | B52: 51 | C52: MTWA02412N11 | D52: TW | E52: Thinwall heat-shrink tubing 2:1, no adhesive (GTW / GTF) | G52: 500 | H52: pcs | I52: 0.042 | J52: 21
A53: CI-26051504 | B53: 52 | C53: MTWA02412R11 | D53: TW | E53: Thinwall heat-shrink tubing 2:1, no adhesive (GTW / GTF) | G53: 300 | H53: pcs | I53: 0.042 | J53: 12.6
A54: CI-26051504 | B54: 53 | C54: MTWA02412X11 | D54: TW | E54: Thinwall heat-shrink tubing 2:1, no adhesive (GTW / GTF) | F54: MTWA25412B11 | G54: 300 | H54: pcs | I54: 0.095 | J54: 28.5
A55: CI-26051504 | B55: 54 | C55: MTWA25412B11 | D55: TW | E55: Thinwall heat-shrink tubing 2:1, no adhesive (GTW / GTF) | F55: 25.4/12.7 | G55: 2500 | H55: pcs | I55: 0.452 | J55: 1130
A56: CI-26051504 | B56: 55 | C56: MTWA25412N11 | D56: TW | E56: Thinwall heat-shrink tubing 2:1, no adhesive (GTW / GTF) | F56: 25.4/12.7 | G56: 2000 | H56: pcs | I56: 0.494 | J56: 988
A57: CI-26051504 | B57: 56 | C57: MTWA03216B11 | D57: TW | E57: Thinwall heat-shrink tubing 2:1, no adhesive (GTW / GTF) | F57: 25.4/12.7 | G57: 7500 | H57: pcs | I57: 0.042 | J57: 315
A58: CI-26051504 | B58: 57 | C58: MTWA03216N11 | D58: TW | E58: Thinwall heat-shrink tubing 2:1, no adhesive (GTW / GTF) | F58: MTWA31815B11 | G58: 3000 | H58: pcs | I58: 0.053 | J58: 159
A59: CI-26051504 | B59: 58 | C59: MTWA31815B11 | D59: TW | E59: Thinwall heat-shrink tubing 2:1, no adhesive (GTW / GTF) | F59: 31.8/15.9 | G59: 1500 | H59: pcs | I59: 0.546 | J59: 819
A60: CI-26051504 | B60: 59 | C60: MTWA31815N11 | D60: TW | E60: Thinwall heat-shrink tubing 2:1, no adhesive (GTW / GTF) | F60: 31.8/15.9 | G60: 400 | H60: pcs | I60: 0.599 | J60: 239.6
...

Sheet Polozky-balici-list
A1: Konsignace / Consignment | B1: Popis z balicího listu / Packing list description | C1: Skupina / Group | D1: Množství / Qty | E1: Čistá hmotnost / Net weight (kg)
A2: CI-26051504 | B2: MSTS 240-3 | C2: KIT | D2: 225 | E2: 192
A3: CI-26051504 | B3: MSTS 240-3 | C3: KIT | D3: 225 | E3: 192
A4: CI-26051504 | B4: MSTS 240-3 | C4: KIT | D4: 180 | E4: 153.6
A5: CI-26051504 | B5: MSTS 16 | C5: KIT | D5: 270 | E5: 54.3
A6: CI-26051504 | B6: MSTS 240 | C6: KIT | D6: 180 | E6: 164.1
A7: CI-26051504 | B7: MSTS 240 GMWT 19/5 Black | C7: KIT | D7: 180 | E7: 164.1
A8: CI-26051504 | B8: GMWT 19/5 Black Mediumwall tube with | C8: MW-A | D8: 4500 | E8: 281.7
A9: CI-26051504 | B9: GMWT 19/5 Black Mediumwall tube with | C9: MW-A | D9: 3900 | E9: 244.14
A10: CI-26051504 | B10: GMWT 19/5 Black Mediumwall tube with | C10: MW-A | D10: 100 | E10: 6
A11: CI-26051504 | B11: GHWT 75/22 Black Heavywall tube with | C11: HW | D11: 50 | E11: 21.6
A12: CI-26051504 | B12: GHWT 19/5 Black Heavywall tube with | C12: HW | D12: 50 | E12: 4.07
A13: CI-26051504 | B13: GHWT 33/8 Black Heavywall tube with | C13: HW | D13: 1500 | E13: 204
... A160: CI-26051902 | B160: Thinwall tube 2:1 MSTS 300 | C160: KIT | D160: 5 | E160: 5.02
B161: CELKEM / TOTAL | D161: =SUM(D2:D160) -> 135205 | E161: =SUM(E2:E160) -> 9643

Sheet Rozpad-dle-produktu
A1: Rozpad podle odesílatele, konsignace a produktové skupiny
A2: Gross weight is not stated per item in the packing lists — only per pallet. It is therefore apportioned pro rata to net weight within each container, so that each container reconciles to its B/L gross weight.
A4: Kontejner / Container | B4: Konsignace | C4: Hrubá hm. celkem (kg) | D4: Čistá hm. celkem (kg)
A5: TGBU9796804 / CNDT11393 | B5: CI-26051504 | C5: 6450 | D5: 5571
A6: TLLU5520254 / CNDT35452 | B6: CI-26051902 | C6: 4980 | D6: 4072
A7: Zdroj / Source: B/L F202615259 (hrubá hm.), balicí listy PL-504 a PL-902 (čistá hm.)
A9: Odesílatel / Sender | B9: Konsignace | C9: Skupina | D9: Popis zboží (CZ) | E9: Description (EN) | F9: HS kód (CN) | G9: Množství / Qty | H9: MJ / Unit | I9: Čistá hm. / Net (kg) | J9: Hrubá hm. / Gross (kg) | K9: Celní hodnota / Value (USD)
A10: Guangdong Grandview Technology Co., Ltd, Dongguan, Guangdong, China | B10: CI-26051504 | C10: HW | D10: Silnostěnná smršťovací trubice s lepidlem | E10: Heavywall heat-shrink tubing with adhesive (GHWT) | F10: 8547 20 00 | G10: =SUMIFS('Polozky-faktury'!$G$2:$G$99,'Polozky-faktury'!$A$2:$A$99,$B10,'Polozky-faktury'!$D$2:$D$99,$C10) -> 5150 | H10: 5,150 pcs | I10: =SUMIFS('Polozky-balici-list'!$E$2:$E$160,'Polozky-balici-list'!$A$2:$A$160,$B10,'Polozky-balici-list'!$C$2:$C$160,$C10) -> 704.71 | J10: =ROUND(I10*$C$5/$D$5,2) -> 815.9 | K10: =SUMIFS('Polozky-faktury'!$J$2:$J$99,'Polozky-faktury'!$A$2:$A$99,$B10,'Polozky-faktury'!$D$2:$D$99,$C10) -> 4811.38
A11: Guangdong Grandview Technology Co., Ltd, Dongguan, Guangdong, China | B11: CI-26051504 | C11: KIT | D11: Sady smršťovacích trubic MSTS (kabelové spojky/koncovky) | E11: MSTS cable jointing/termination kits (sets of heat-shrink tubes) | F11: 8547 20 00 | G11: =SUMIFS('Polozky-faktury'!$G$2:$G$99,'Polozky-faktury'!$A$2:$A$99,$B11,'Polozky-faktury'!$D$2:$D$99,$C11) -> 2340 | H11: 2,340 kit | I11: =SUMIFS('Polozky-balici-list'!$E$2:$E$160,'Polozky-balici-list'!$A$2:$A$160,$B11,'Polozky-balici-list'!$C$2:$C$160,$C11) -> 1136.96 | J11: =ROUND(I11*$C$5/$D$5,2) -> 1316.35 | K11: =SUMIFS('Polozky-faktury'!$J$2:$J$99,'Polozky-faktury'!$A$2:$A$99,$B11,'Polozky-faktury'!$D$2:$D$99,$C11) -> 6347.52
A12: Guangdong Grandview Technology Co., Ltd, Dongguan, Guangdong, China | B12: CI-26051504 | C12: MW-A | D12: Středněstěnná smršťovací trubice s lepidlem | E12: Mediumwall heat-shrink tubing with adhesive (GMWT) | F12: 8547 20 00 | G12: =SUMIFS('Polozky-faktury'!$G$2:$G$99,'Polozky-faktury'!$A$2:$A$99,$B12,'Polozky-faktury'!$D$2:$D$99,$C12) -> 23195 | H12: 23,195 pcs | I12: =SUMIFS('Polozky-balici-list'!$E$2:$E$160,'Polozky-balici-list'!$A$2:$A$160,$B12,'Polozky-balici-list'!$C$2:$C$160,$C12) -> 2182.49 | J12: =ROUND(I12*$C$5/$D$5,2) -> 2526.85 | K12: =SUMIFS('Polozky-faktury'!$J$2:$J$99,'Polozky-faktury'!$A$2:$A$99,$B12,'Polozky-faktury'!$D$2:$D$99,$C12) -> 16997.44
A13: Guangdong Grandview Technology Co., Ltd, Dongguan, Guangdong, China | B13: CI-26051504 | C13: MW-U | D13: Středněstěnná smršťovací trubice bez lepidla | E13: Mediumwall heat-shrink tubing without adhesive (GMWT/U) | F13: 8547 20 00 | G13: =SUMIFS('Polozky-faktury'!$G$2:$G$99,'Polozky-faktury'!$A$2:$A$99,$B13,'Polozky-faktury'!$D$2:$D$99,$C13) -> 480 | H13: 480 pcs | I13: =SUMIFS('Polozky-balici-list'!$E$2:$E$160,'Polozky-balici-list'!$A$2:$A$160,$B13,'Polozky-balici-list'!$C$2:$C$160,$C13) -> 32.72 | J13: =ROUND(I13*$C$5/$D$5,2) -> 37.88 | K13: =SUMIFS('Polozky-faktury'!$J$2:$J$99,'Polozky-faktury'!$A$2:$A$99,$B13,'Polozky-faktury'!$D$2:$D$99,$C13) -> 291.84
A14: Guangdong Grandview Technology Co., Ltd, Dongguan, Guangdong, China | B14: CI-26051504 | C14: OTH | D14: Tiskové/značkovací kolečko - nespecifikováno | E14: Type wheel (printing/marking wheel) - not identified | F14: k určení / TBC | G14: =SUMIFS('Polozky-faktury'!$G$2:$G$99,'Polozky-faktury'!$A$2:$A$99,$B14,'Polozky-faktury'!$D$2:$D$99,$C14) -> 3 | H14: 3 - | I14: =SUMIFS('Polozky-balici-list'!$E$2:$E$160,'Polozky-balici-list'!$A$2:$A$160,$B14,'Polozky-balici-list'!$C$2:$C$160,$C14) -> 0 | J14: =ROUND(I14*$C$5/$D$5,2) -> 0 | K14: =SUMIFS('Polozky-faktury'!$J$2:$J$99,'Polozky-faktury'!$A$2:$A$99,$B14,'Polozky-faktury'!$D$2:$D$99,$C14) -> 120
A15: Guangdong Grandview Technology Co., Ltd, Dongguan, Guangdong, China | B15: CI-26051504 | C15: TW | D15: Tenkostěnná smršťovací bužírka 2:1, bez lepidla | E15: Thinwall heat-shrink tubing 2:1, no adhesive (GTW / GTF) | F15: 8547 20 00 | G15: =SUMIFS('Polozky-faktury'!$G$2:$G$99,'Polozky-faktury'!$A$2:$A$99,$B15,'Polozky-faktury'!$D$2:$D$99,$C15) -> 81380 | H15: 4,250 m + 77,130 pcs | I15: =SUMIFS('Polozky-balici-list'!$E$2:$E$160,'Polozky-balici-list'!$A$2:$A$160,$B15,'Polozky-balici-list'!$C$2:$C$160,$C15) -> 1514.12 | J15: =ROUND(I15*$C$5/$D$5,2) -> 1753.02 | K15: =SUMIFS('Polozky-faktury'!$J$2:$J$99,'Polozky-faktury'!$A$2:$A$99,$B15,'Polozky-faktury'!$D$2:$D$99,$C15) -> 14385.43
A16: Guangdong Grandview Technology Co., Ltd, Dongguan, Guangdong, China | B16: CI-26051902 | C16: HW | D16: Silnostěnná smršťovací trubice s lepidlem | E16: Heavywall heat-shrink tubing with adhesive (GHWT) | F16: 8547 20 00 | G16: =SUMIFS('Polozky-faktury'!$G$2:$G$99,'Polozky-faktury'!$A$2:$A$99,$B16,'Polozky-faktury'!$D$2:$D$99,$C16) -> 110 | H16: 110 pcs | I16: =SUMIFS('Polozky-balici-list'!$E$2:$E$160,'Polozky-balici-list'!$A$2:$A$160,$B16,'Polozky-balici-list'!$C$2:$C$160,$C16) -> 58.66 | J16: =ROUND(I16*$C$6/$D$6,2) -> 71.74 | K16: =SUMIFS('Polozky-faktury'!$J$2:$J$99,'Polozky-faktury'!$A$2:$A$99,$B16,'Polozky-faktury'!$D$2:$D$99,$C16) -> 376.69
A17: Guangdong Grandview Technology Co., Ltd, Dongguan, Guangdong, China | B17: CI-26051902 | C17: KIT | D17: Sady smršťovacích trubic MSTS (kabelové spojky/koncovky) | E17: MSTS cable jointing/termination kits (sets of heat-shrink tubes) | F17: 8547 20 00 | G17: =SUMIFS('Polozky-faktury'!$G$2:$G$99,'Polozky-faktury'!$A$2:$A$99,$B17,'Polozky-faktury'!$D$2:$D$99,$C17) -> 7190 | H17: 7,190 kit | I17: =SUMIFS('Polozky-balici-list'!$E$2:$E$160,'Polozky-balici-list'!$A$2:$A$160,$B17,'Polozky-balici-list'!$C$2:$C$160,$C17) -> 3351.86 | J17: =ROUND(I17*$C$6/$D$6,2) -> 4099.28 | K17: =SUMIFS('Polozky-faktury'!$J$2:$J$99,'Polozky-faktury'!$A$2:$A$99,$B17,'Polozky-faktury'!$D$2:$D$99,$C17) -> 17612.08
A18: Guangdong Grandview Technology Co., Ltd, Dongguan, Guangdong, China | B18: CI-26051902 | C18: TW | D18: Tenkostěnná smršťovací bužírka 2:1, bez lepidla | E18: Thinwall heat-shrink tubing 2:1, no adhesive (GTW / GTF) | F18: 8547 20 00 | G18: =SUMIFS('Polozky-faktury'!$G$2:$G$99,'Polozky-faktury'!$A$2:$A$99,$B18,'Polozky-faktury'!$D$2:$D$99,$C18) -> 15360 | H18: 15,360 pcs | I18: =SUMIFS('Polozky-balici-list'!$E$2:$E$160,'Polozky-balici-list'!$A$2:$A$160,$B18,'Polozky-balici-list'!$C$2:$C$160,$C18) -> 661.48 | J18: =ROUND(I18*$C$6/$D$6,2) -> 808.98 | K18: =SUMIFS('Polozky-faktury'!$J$2:$J$99,'Polozky-faktury'!$A$2:$A$99,$B18,'Polozky-faktury'!$D$2:$D$99,$C18) -> 6120.94
E19: CELKEM / TOTAL | G19: =SUM(G10:G18) -> 135208 | I19: =SUM(I10:I18) -> 9643 | J19: =SUM(J10:J18) -> 11430 | K19: =SUM(K10:K18) -> 67063.32

Sheet Poznamky
A1: POZNÁMKY A UPOZORNĚNÍ / NOTES & FLAGS
A3: Bod / Item | B3: Status | C3: Popis / Detail
A4: 1. PREFERENČNÍ VĚTA — NENALEZENA | B4: KRITICKÉ | C4: Ani na jedné faktuře (CI-26051504, CI-26051902) ani v balicích listech NENÍ preferenční věta / prohlášení o preferenčním původu. Obě faktury uvádějí pouze "Country of Origin: CHINA". Pozn.: EU nemá s Čínou dohodu o volném obchodu, takže preferenční sazba pro čínský původ NEEXISTUJE — preferenční věta by zde stejně nepomohla. Uplatní se plná třetizemní (erga omnes) celní sazba. Sazbu ověřte v TARIC k datu propuštění.
A5: 2. INCOTERM — chybí místo | B5: DOPLNIT | C5: Faktury i balicí listy uvádějí pouze "Inco Terms: EXW", BEZ jmenovaného místa. Podle pravidel má být uvedeno i město. Pravděpodobně EXW Dongguan (sídlo/závod odesílatele, Guangdong, Čína), ale v dokladech to uvedeno NENÍ — nechal jsem to nedoplněné, prosím potvrď skutečné místo. Pozor i na dopad na celní hodnotu: při EXW se k ceně zboží přičítají náklady na dopravu do hranic EU; B/L je FREIGHT COLLECT, takže dopravné není ve fakturované částce.
A6: 3. HS KÓDY NA FAKTURÁCH — prázdné | B6: ZJIŠTĚNO | C6: Obě faktury mají sloupec "HS CODE", ale je ve VŠECH řádcích prázdný — dodavatel jej nevyplnil. Klasifikaci jsem proto provedl sám (viz bod 4). Doporučuji vyžádat od dodavatele doplnění.
A7: 4. NAVRŽENÁ KLASIFIKACE — 8547 20 00 | B7: K ODSOUHLASENÍ | C7: Navrhuji 8547 20 00 (izolační části a součásti z plastů pro elektrická zařízení) pro veškeré smršťovací trubice, bužírky i sady MSTS. Odůvodnění: pozn. 8 ke kap. 39 omezuje číslo 3917 na trubky "používané k dopravě, vedení nebo rozvodu plynů či kapalin" — smršťovací izolační bužírka tuto podmínku nesplňuje, takže 3917 je právně vyloučeno. Pozn. 2 ke kap. 39 navíc vylučuje výrobky třídy XVI. Sady MSTS: dle VIP 3 b) podle materiálu určujícího podstatný charakter = rovněž trubice. ALTERNATIVA: pokud by celní úřad považoval zboží za běžný materiál v metráži, nikoli za "izolační části", připadá v úvahu 3926 90 97. Vzhledem k hodnotě a opakovanosti dodávek DOPORUČUJI požádat o ZIS/BTI.
A8: 5. B/L UVÁDÍ JINÝ KÓD — 8547 90 00 | B8: NESOULAD | C8: Konosament F202615259 deklaruje "HS CODE: 85479000" pro celou zásilku. To je nesprávná podpoložka: 8547 90 00 je zbytková položka pokrývající zejména elektrickou instalační trubku z obecného kovu vyloženou izolačním materiálem. Pro výrobky zcela z plastu je správně 8547 20 00. Číslo (8547) tedy odesílatel zvolil správně, podpoložku nikoli.
A9: 6. TYPE WHEEL — 3 ks bez balicího listu | B9: NESOULAD | C9: Faktura CI-26051504, řádek 78: "type wheel", 3 ks, 40,00 USD/ks = 120,00 USD. Tato položka NENÍ v balicím listu PL-504: fakturované množství 112 548 ks vs. balicí list 112 545 ks — rozdíl přesně 3 ks. Nemá tedy uvedenou žádnou hmotnost a není jasné, zda je fyzicky v kontejneru. Nelze ani spolehlivě zařadit — podle povahy buď 8442 50 00 (tiskařské typy/štočky), nebo 8443 99 (části tiskáren). Prosím o upřesnění, co to je, a zda je zboží v zásilce.
A10: 7. CBAM — nepodléhá | B10: OK | C10: Zásilka nepodléhá CBAM. CBAM (nařízení (EU) 2023/956, příloha I) pokrývá cement, elektřinu, hnojiva, železo a ocel, hliník a vodík. Plasty (kap. 39) ani zboží kap. 85 do rozsahu nespadají. Rozšíření na polymery se očekává až s pozdějším rozšířením rozsahu.
A11: 8. ANTIDUMPING — nezjištěno | B11: OK | C11: Pro smršťovací bužírky / izolační části z plastů čínského původu (8547 20 00, ani alternativní 3926 90 97 či 3917) nebylo zjištěno žádné platné antidumpingové ani vyrovnávací opatření EU. Doporučuji standardní ověření v TARIC k datu celního prohlášení.
A12: 9. HRUBÁ HMOTNOST — rozpočítána | B12: METODIKA | C12: Balicí listy uvádějí hrubou hmotnost pouze po paletách, nikoli po položkách. Hrubá hmotnost je proto rozpočítána poměrem k čisté hmotnosti v rámci každého kontejneru (TGBU9796804: 6 450,00 / 5 571,00 kg; TLLU5520254: 4 980,00 / 4 072,00 kg). Součet odpovídá B/L: 11 430,00 kg.
A13: 10. KONTROLNÍ SOUČTY — sedí | B13: OK | C13: Celní hodnota 67 063,32 USD = CI-26051504 (42 953,61) + CI-26051902 (24 109,71), na cent. Čistá hmotnost 9 643,00 kg = PL-504 (5 571,00) + PL-902 (4 072,00). Hrubá hmotnost 11 430,00 kg = B/L F202615259. Množství podle faktur a balicích listů souhlasí u všech skupin kromě položky "type wheel" (bod 6).
A14: 11. POPISY V ČEŠTINĚ | B14: INFO | C14: Zdrojové doklady jsou pouze v angličtině — český popis se v nich nevyskytuje. České popisy ve sloupci "Popis zboží (CZ)" jsem proto doplnil podle znění kombinované nomenklatury a povahy zboží; anglický originál je ponechán ve vedlejším sloupci pro kontrolu.
