Workbook

Sheet HS Summary
A1: Souhrn HS kódů – 4Leaders, s.r.o. – zásilka 2026P11
A2: Odesílatel: Yiwu Jingsourcing Ecommerce Co Limited | Příjemce: 4Leaders, s.r.o., Příběnická 695/5, 390 01 Tábor, CZ | Faktura JW20260707P11 ze 7.7.2026 | B/L F202616283 | Kontejner MRKU5068835 (1×40'HQ), 608 kartonů | Incoterm: FOB Ningbo
A3: Čistá hmotnost doplněna z revidovaného packing listu „Packing list-P11net weight.xlsx“ (sloupec „gross weight / each product / kg“). U 3 položek byla hodnota dodavatele nepoužitelná – viz list „Dokumenty a poznámky“.
A5: Odesílatel | B5: HS kód | C5: Popis zboží (CZ) | D5: Země původu (COO) | E5: Celkové množství (ks) | F5: Čistá hmotnost (kg) | G5: Hrubá hmotnost (kg) | H5: Hodnota USD – před slevou | I5: Hodnota USD – po slevě | J5: Incoterm | K5: Příznak | L5: TARIC / poznámka / CBAM / Antidumping
A6: Yiwu Jingsourcing Ecommerce Co Limited, Yiwu, Zhejiang, CN | B6: 3406000000 | C6: Kouzelná svíčka; Kouzelná svíčka - čtyřstěnná pyramida; Kouzelná svíčka - srdce; Plovoucí svíčky 10 ks - bílá | D6: CN | E6: =SUMIF(Položky!$B$4:$B$63,$B6,Položky!G$4:G$63) -> 10344 | F6: =ROUND(SUMIF(Položky!$B$4:$B$63,$B6,Položky!K$4:K$63),3) -> 1383.907 | G6: =ROUND(SUMIF(Položky!$B$4:$B$63,$B6,Položky!L$4:L$63),3) -> 1493 | H6: =ROUND(SUMIF(Položky!$B$4:$B$63,$B6,Položky!N$4:N$63),2) -> 12976.4 | I6: =ROUND(H6*$C$55,2) -> 12065.84 | J6: FOB Ningbo | K6: ANTIDUMPING | L6: ANTIDUMPINGOVÉ CLO – svíčky z ČLR. Stejná sazba jako u zásilky Czech Healthcare 196652 (A00 60,3 % / 21 %). Ověřit aktuální sazbu a základ cla v TARIC při podání JSD. Čistá hmotnost dopočtena u položky č. 6 – dodavatel uvedl nemožnou hodnotu.
A7: Yiwu Jingsourcing Ecommerce Co Limited, Yiwu, Zhejiang, CN | B7: 9503007590 | C7: RC Sportovní transformující se autíčko na dálkové ovládání - červené; Vláček stavějící domino; Solarbot 3v1 | D7: CN | E7: =SUMIF(Položky!$B$4:$B$63,$B7,Položky!G$4:G$63) -> 3720 | F7: =ROUND(SUMIF(Položky!$B$4:$B$63,$B7,Položky!K$4:K$63),3) -> 1598.352 | G7: =ROUND(SUMIF(Položky!$B$4:$B$63,$B7,Položky!L$4:L$63),3) -> 1673 | H7: =ROUND(SUMIF(Položky!$B$4:$B$63,$B7,Položky!N$4:N$63),2) -> 10954.9 | I7: =ROUND(H7*$C$55,2) -> 10186.19 | J7: FOB Ningbo
A8: Yiwu Jingsourcing Ecommerce Co Limited, Yiwu, Zhejiang, CN | B8: 9503009590 | C8: Kouzelné kreslení; Přesouvačka - Parkoviště s autíčky; Basketbalový koš na dveře - sada s míčkem a pumpičkou | D8: CN | E8: =SUMIF(Položky!$B$4:$B$63,$B8,Položky!G$4:G$63) -> 3456 | F8: =ROUND(SUMIF(Položky!$B$4:$B$63,$B8,Položky!K$4:K$63),3) -> 1087.152 | G8: =ROUND(SUMIF(Položky!$B$4:$B$63,$B8,Položky!L$4:L$63),3) -> 1117 | H8: =ROUND(SUMIF(Položky!$B$4:$B$63,$B8,Položky!N$4:N$63),2) -> 6096.6 | I8: =ROUND(H8*$C$55,2) -> 5668.8 | J8: FOB Ningbo
A9: Yiwu Jingsourcing Ecommerce Co Limited, Yiwu, Zhejiang, CN | B9: 9503006900 | C9: IQ Puzzle 3D; Hlavolam rotační věž; Puzzle pro děti - zvířátka | D9: CN | E9: =SUMIF(Položky!$B$4:$B$63,$B9,Položky!G$4:G$63) -> 6320 | F9: =ROUND(SUMIF(Položky!$B$4:$B$63,$B9,Položky!K$4:K$63),3) -> 371.08 | G9: =ROUND(SUMIF(Položky!$B$4:$B$63,$B9,Položky!L$4:L$63),3) -> 394 | H9: =ROUND(SUMIF(Položky!$B$4:$B$63,$B9,Položky!N$4:N$63),2) -> 6032.2 | I9: =ROUND(H9*$C$55,2) -> 5608.92 | J9: FOB Ningbo | K9: ČISTÁ HM. DOPOČTENA | L9: Čistá hmotnost dopočtena u položky č. 9 – dodavatel uvedl nemožnou hodnotu.
A10: Yiwu Jingsourcing Ecommerce Co Limited, Yiwu, Zhejiang, CN | B10: 6301401000 | C10: Svítící deka - jednorožec | D10: CN | E10: =SUMIF(Položky!$B$4:$B$63,$B10,Položky!G$4:G$63) -> 2100 | F10: =ROUND(SUMIF(Položky!$B$4:$B$63,$B10,Položky!K$4:K$63),3) -> 882 | G10: =ROUND(SUMIF(Položky!$B$4:$B$63,$B10,Položky!L$4:L$63),3) -> 924 | H10: =ROUND(SUMIF(Položky!$B$4:$B$63,$B10,Položky!N$4:N$63),2) -> 4300.8 | I10: =ROUND(H10*$C$55,2) -> 3999.01 | J10: FOB Ningbo
A11: Yiwu Jingsourcing Ecommerce Co Limited, Yiwu, Zhejiang, CN | B11: 6304930090 | C11: Vánoční svítící povlak na polštář - vánoční chaloupka | D11: CN | E11: =SUMIF(Položky!$B$4:$B$63,$B11,Položky!G$4:G$63) -> 4350 | F11: =ROUND(SUMIF(Položky!$B$4:$B$63,$B11,Položky!K$4:K$63),3) -> 435 | G11: =ROUND(SUMIF(Položky!$B$4:$B$63,$B11,Položky!L$4:L$63),3) -> 456.75 | H11: =ROUND(SUMIF(Položky!$B$4:$B$63,$B11,Položky!N$4:N$63),2) -> 4167.3 | I11: =ROUND(H11*$C$55,2) -> 3874.88 | J11: FOB Ningbo
A12: Yiwu Jingsourcing Ecommerce Co Limited, Yiwu, Zhejiang, CN | B12: 9503005590 | C12: Tančící vánoční stromeček - zpívající | D12: CN | E12: =SUMIF(Položky!$B$4:$B$63,$B12,Položky!G$4:G$63) -> 900 | F12: =ROUND(SUMIF(Položky!$B$4:$B$63,$B12,Položky!K$4:K$63),3) -> 360 | G12: =ROUND(SUMIF(Položky!$B$4:$B$63,$B12,Položky!L$4:L$63),3) -> 378 | H12: =ROUND(SUMIF(Položky!$B$4:$B$63,$B12,Položky!N$4:N$63),2) -> 3852 | I12: =ROUND(H12*$C$55,2) -> 3581.7 | J12: FOB Ningbo
A13: Yiwu Jingsourcing Ecommerce Co Limited, Yiwu, Zhejiang, CN | B13: 9404909000 | C13: Polštář s nožičkami - fotbalový míč | D13: CN | E13: =SUMIF(Položky!$B$4:$B$63,$B13,Položky!G$4:G$63) -> 1600 | F13: =ROUND(SUMIF(Položky!$B$4:$B$63,$B13,Položky!K$4:K$63),3) -> 590.4 | G13: =ROUND(SUMIF(Položky!$B$4:$B$63,$B13,Položky!L$4:L$63),3) -> 600 | H13: =ROUND(SUMIF(Položky!$B$4:$B$63,$B13,Položky!N$4:N$63),2) -> 3510.4 | I13: =ROUND(H13*$C$55,2) -> 3264.07 | J13: FOB Ningbo
A14: Yiwu Jingsourcing Ecommerce Co Limited, Yiwu, Zhejiang, CN | B14: 9503007000 | C14: Textilní tvoření pro princezny; Diamantové malování - strom; Didaktická hra se zvířátky - Prostorové vnímání; Velká vyškrabávací sada s vánočními motivy | D14: CN | E14: =SUMIF(Položky!$B$4:$B$63,$B14,Položky!G$4:G$63) -> 2360 | F14: =ROUND(SUMIF(Položky!$B$4:$B$63,$B14,Položky!K$4:K$63),3) -> 254.66 | G14: =ROUND(SUMIF(Položky!$B$4:$B$63,$B14,Položky!L$4:L$63),3) -> 274.333 | H14: =ROUND(SUMIF(Položky!$B$4:$B$63,$B14,Položky!N$4:N$63),2) -> 2646.1 | I14: =ROUND(H14*$C$55,2) -> 2460.42 | J14: FOB Ningbo
A15: Yiwu Jingsourcing Ecommerce Co Limited, Yiwu, Zhejiang, CN | B15: 6601910000 | C15: Deštník s kočkami | D15: CN | E15: =SUMIF(Položky!$B$4:$B$63,$B15,Položky!G$4:G$63) -> 720 | F15: =ROUND(SUMIF(Položky!$B$4:$B$63,$B15,Položky!K$4:K$63),3) -> 239.76 | G15: =ROUND(SUMIF(Položky!$B$4:$B$63,$B15,Položky!L$4:L$63),3) -> 252 | H15: =ROUND(SUMIF(Položky!$B$4:$B$63,$B15,Položky!N$4:N$63),2) -> 2353 | I15: =ROUND(H15*$C$55,2) -> 2187.89 | J15: FOB Ningbo | K15: K OVĚŘENÍ | L15: Deštníky z ČLR – historicky předmět antidumpingových opatření. OVĚŘIT v TARIC, zda jsou opatření stále v platnosti.
A16: Yiwu Jingsourcing Ecommerce Co Limited, Yiwu, Zhejiang, CN | B16: 9405423990 | C16: Vánoční LED kovová hvězda; Elegantní svítící růže ve skleněné váze | D16: CN | E16: =SUMIF(Položky!$B$4:$B$63,$B16,Položky!G$4:G$63) -> 904 | F16: =ROUND(SUMIF(Položky!$B$4:$B$63,$B16,Položky!K$4:K$63),3) -> 217.832 | G16: =ROUND(SUMIF(Položky!$B$4:$B$63,$B16,Položky!L$4:L$63),3) -> 249 | H16: =ROUND(SUMIF(Položky!$B$4:$B$63,$B16,Položky!N$4:N$63),2) -> 1915.4 | I16: =ROUND(H16*$C$55,2) -> 1781 | J16: FOB Ningbo
A17: Yiwu Jingsourcing Ecommerce Co Limited, Yiwu, Zhejiang, CN | B17: 6307909899 | C17: Zatemňující odnímatelná okenní fólie 140x100 cm | D17: CN | E17: =SUMIF(Položky!$B$4:$B$63,$B17,Položky!G$4:G$63) -> 1200 | F17: =ROUND(SUMIF(Položky!$B$4:$B$63,$B17,Položky!K$4:K$63),3) -> 255.6 | G17: =ROUND(SUMIF(Položky!$B$4:$B$63,$B17,Položky!L$4:L$63),3) -> 270 | H17: =ROUND(SUMIF(Položky!$B$4:$B$63,$B17,Položky!N$4:N$63),2) -> 1836 | I17: =ROUND(H17*$C$55,2) -> 1707.17 | J17: FOB Ningbo
A18: Yiwu Jingsourcing Ecommerce Co Limited, Yiwu, Zhejiang, CN | B18: 7009920000 | C18: Cestovní kosmetické zrcátko s podsvícením | D18: CN | E18: =SUMIF(Položky!$B$4:$B$63,$B18,Položky!G$4:G$63) -> 600 | F18: =ROUND(SUMIF(Položky!$B$4:$B$63,$B18,Položky!K$4:K$63),3) -> 51.18 | G18: =ROUND(SUMIF(Položky!$B$4:$B$63,$B18,Položky!L$4:L$63),3) -> 54 | H18: =ROUND(SUMIF(Položky!$B$4:$B$63,$B18,Položky!N$4:N$63),2) -> 1537.2 | I18: =ROUND(H18*$C$55,2) -> 1429.33 | J18: FOB Ningbo | K18: ČISTÁ HM. DOPOČTENA | L18: Čistá hmotnost dopočtena u položky č. 4 – dodavatel uvedl nemožnou hodnotu.
A19: Yiwu Jingsourcing Ecommerce Co Limited, Yiwu, Zhejiang, CN | B19: 8513100000 | C19: Nabíjecí čelovka | D19: CN | E19: =SUMIF(Položky!$B$4:$B$63,$B19,Položky!G$4:G$63) -> 920 | F19: =ROUND(SUMIF(Položky!$B$4:$B$63,$B19,Položky!K$4:K$63),3) -> 76.36 | G19: =ROUND(SUMIF(Položky!$B$4:$B$63,$B19,Položky!L$4:L$63),3) -> 84.333 | H19: =ROUND(SUMIF(Položky!$B$4:$B$63,$B19,Položky!N$4:N$63),2) -> 1517.1 | I19: =ROUND(H19*$C$55,2) -> 1410.64 | J19: FOB Ningbo
A20: Yiwu Jingsourcing Ecommerce Co Limited, Yiwu, Zhejiang, CN | B20: 6302329000 | C20: Mikroplyšové prostěradlo 90 x 200 cm - tmavě šedé; Mikroplyšové prostěradlo 180 x 200 cm - tmavě šedé | D20: CN | E20: =SUMIF(Položky!$B$4:$B$63,$B20,Položky!G$4:G$63) -> 350 | F20: =ROUND(SUMIF(Položky!$B$4:$B$63,$B20,Položky!K$4:K$63),3) -> 138.35 | G20: =ROUND(SUMIF(Položky!$B$4:$B$63,$B20,Položky!L$4:L$63),3) -> 141 | H20: =ROUND(SUMIF(Položky!$B$4:$B$63,$B20,Položky!N$4:N$63),2) -> 1481.1 | I20: =ROUND(H20*$C$55,2) -> 1377.17 | J20: FOB Ningbo
A21: Yiwu Jingsourcing Ecommerce Co Limited, Yiwu, Zhejiang, CN | B21: 9405423100 | C21: LED RGB pásek s ovladačem - 2 m; Vánoční LED svítící koule na stromeček - girlanda; LED světelný panel reagující na zvuk - černý | D21: CN | E21: =SUMIF(Položky!$B$4:$B$63,$B21,Položky!G$4:G$63) -> 1180 | F21: =ROUND(SUMIF(Položky!$B$4:$B$63,$B21,Položky!K$4:K$63),3) -> 60 | G21: =ROUND(SUMIF(Položky!$B$4:$B$63,$B21,Položky!L$4:L$63),3) -> 73 | H21: =ROUND(SUMIF(Položky!$B$4:$B$63,$B21,Položky!N$4:N$63),2) -> 1375.6 | I21: =ROUND(H21*$C$55,2) -> 1279.07 | J21: FOB Ningbo
A22: Yiwu Jingsourcing Ecommerce Co Limited, Yiwu, Zhejiang, CN | B22: 9615190000 | C22: Velká sada ozdob do vlasů | D22: CN | E22: =SUMIF(Položky!$B$4:$B$63,$B22,Položky!G$4:G$63) -> 1500 | F22: =ROUND(SUMIF(Položky!$B$4:$B$63,$B22,Položky!K$4:K$63),3) -> 189 | G22: =ROUND(SUMIF(Položky!$B$4:$B$63,$B22,Položky!L$4:L$63),3) -> 196.262 | H22: =ROUND(SUMIF(Položky!$B$4:$B$63,$B22,Položky!N$4:N$63),2) -> 1375.5 | I22: =ROUND(H22*$C$55,2) -> 1278.98 | J22: FOB Ningbo
A23: Yiwu Jingsourcing Ecommerce Co Limited, Yiwu, Zhejiang, CN | B23: 6110309900 | C23: Dětská svítící mikina - hvězdy | D23: CN | E23: =SUMIF(Položky!$B$4:$B$63,$B23,Položky!G$4:G$63) -> 300 | F23: =ROUND(SUMIF(Položky!$B$4:$B$63,$B23,Položky!K$4:K$63),3) -> 120 | G23: =ROUND(SUMIF(Položky!$B$4:$B$63,$B23,Položky!L$4:L$63),3) -> 126 | H23: =ROUND(SUMIF(Položky!$B$4:$B$63,$B23,Položky!N$4:N$63),2) -> 1305 | I23: =ROUND(H23*$C$55,2) -> 1213.43 | J23: FOB Ningbo
A24: Yiwu Jingsourcing Ecommerce Co Limited, Yiwu, Zhejiang, CN | B24: 6306220000 | C24: Dětský stan vesmírná raketa | D24: CN | E24: =SUMIF(Položky!$B$4:$B$63,$B24,Položky!G$4:G$63) -> 120 | F24: =ROUND(SUMIF(Položky!$B$4:$B$63,$B24,Položky!K$4:K$63),3) -> 92.04 | G24: =ROUND(SUMIF(Položky!$B$4:$B$63,$B24,Položky!L$4:L$63),3) -> 96 | H24: =ROUND(SUMIF(Položky!$B$4:$B$63,$B24,Položky!N$4:N$63),2) -> 906 | I24: =ROUND(H24*$C$55,2) -> 842.43 | J24: FOB Ningbo
A25: Yiwu Jingsourcing Ecommerce Co Limited, Yiwu, Zhejiang, CN | B25: 6115950000 | C25: Prstové ponožky - kočky | D25: CN | E25: =SUMIF(Položky!$B$4:$B$63,$B25,Položky!G$4:G$63) -> 1000 | F25: =ROUND(SUMIF(Položky!$B$4:$B$63,$B25,Položky!K$4:K$63),3) -> 38 | G25: =ROUND(SUMIF(Položky!$B$4:$B$63,$B25,Položky!L$4:L$63),3) -> 40 | H25: =ROUND(SUMIF(Položky!$B$4:$B$63,$B25,Položky!N$4:N$63),2) -> 894 | I25: =ROUND(H25*$C$55,2) -> 831.27 | J25: FOB Ningbo | K25: K OVĚŘENÍ | L25: Doplňková jednotka u ponožek je PÁR. V dokladech není uvedeno, zda 1 000 ks = 1 000 párů. OVĚŘIT u dodavatele.
A26: Yiwu Jingsourcing Ecommerce Co Limited, Yiwu, Zhejiang, CN | B26: 6308000020 | C26: Vyšívání pro děti - jednorožec | D26: CN | E26: =SUMIF(Položky!$B$4:$B$63,$B26,Položky!G$4:G$63) -> 360 | F26: =ROUND(SUMIF(Položky!$B$4:$B$63,$B26,Položky!K$4:K$63),3) -> 29.88 | G26: =ROUND(SUMIF(Položky!$B$4:$B$63,$B26,Položky!L$4:L$63),3) -> 33 | H26: =ROUND(SUMIF(Položky!$B$4:$B$63,$B26,Položky!N$4:N$63),2) -> 721.8 | I26: =ROUND(H26*$C$55,2) -> 671.15 | J26: FOB Ningbo
A27: Yiwu Jingsourcing Ecommerce Co Limited, Yiwu, Zhejiang, CN | B27: 9506999000 | C27: Tančící housenka | D27: CN | E27: =SUMIF(Položky!$B$4:$B$63,$B27,Položky!G$4:G$63) -> 180 | F27: =ROUND(SUMIF(Položky!$B$4:$B$63,$B27,Položky!K$4:K$63),3) -> 129.96 | G27: =ROUND(SUMIF(Položky!$B$4:$B$63,$B27,Položky!L$4:L$63),3) -> 135 | H27: =ROUND(SUMIF(Položky!$B$4:$B$63,$B27,Položky!N$4:N$63),2) -> 702 | I27: =ROUND(H27*$C$55,2) -> 652.74 | J27: FOB Ningbo
A28: Yiwu Jingsourcing Ecommerce Co Limited, Yiwu, Zhejiang, CN | B28: 9503009990 | C28: Dětská magnetická hra v kufříku oblékání panenek | D28: CN | E28: =SUMIF(Položky!$B$4:$B$63,$B28,Položky!G$4:G$63) -> 180 | F28: =ROUND(SUMIF(Položky!$B$4:$B$63,$B28,Položky!K$4:K$63),3) -> 129.96 | G28: =ROUND(SUMIF(Položky!$B$4:$B$63,$B28,Položky!L$4:L$63),3) -> 135 | H28: =ROUND(SUMIF(Položky!$B$4:$B$63,$B28,Položky!N$4:N$63),2) -> 678.6 | I28: =ROUND(H28*$C$55,2) -> 630.98 | J28: FOB Ningbo
A29: Yiwu Jingsourcing Ecommerce Co Limited, Yiwu, Zhejiang, CN | B29: 9503004990 | C29: Pěnová zvířátka do vany 15 ks; Hračka do vany - fontána s krokodýlem | D29: CN | E29: =SUMIF(Položky!$B$4:$B$63,$B29,Položky!G$4:G$63) -> 270 | F29: =ROUND(SUMIF(Položky!$B$4:$B$63,$B29,Položky!K$4:K$63),3) -> 50.04 | G29: =ROUND(SUMIF(Položky!$B$4:$B$63,$B29,Položky!L$4:L$63),3) -> 53 | H29: =ROUND(SUMIF(Položky!$B$4:$B$63,$B29,Položky!N$4:N$63),2) -> 670 | I29: =ROUND(H29*$C$55,2) -> 622.99 | J29: FOB Ningbo
A30: Yiwu Jingsourcing Ecommerce Co Limited, Yiwu, Zhejiang, CN | B30: 8543709099 | C30: Aplikátor na lepení kamínků + sada kamínků | D30: CN | E30: =SUMIF(Položky!$B$4:$B$63,$B30,Položky!G$4:G$63) -> 150 | F30: =ROUND(SUMIF(Položky!$B$4:$B$63,$B30,Položky!K$4:K$63),3) -> 39 | G30: =ROUND(SUMIF(Položky!$B$4:$B$63,$B30,Položky!L$4:L$63),3) -> 42 | H30: =ROUND(SUMIF(Položky!$B$4:$B$63,$B30,Položky!N$4:N$63),2) -> 645.6 | I30: =ROUND(H30*$C$55,2) -> 600.3 | J30: FOB Ningbo
A31: Yiwu Jingsourcing Ecommerce Co Limited, Yiwu, Zhejiang, CN | B31: 7013499900 | C31: Otočný stojan se skleněnými kořenkami 18 ks | D31: CN | E31: =SUMIF(Položky!$B$4:$B$63,$B31,Položky!G$4:G$63) -> 144 | F31: =ROUND(SUMIF(Položky!$B$4:$B$63,$B31,Položky!K$4:K$63),3) -> 348.048 | G31: =ROUND(SUMIF(Položky!$B$4:$B$63,$B31,Položky!L$4:L$63),3) -> 360 | H31: =ROUND(SUMIF(Položky!$B$4:$B$63,$B31,Položky!N$4:N$63),2) -> 640.2 | I31: =ROUND(H31*$C$55,2) -> 595.28 | J31: FOB Ningbo | K31: K OVĚŘENÍ | L31: Stolní/kuchyňské sklo z ČLR – OVĚŘIT v TARIC případná antidumpingová opatření.
A32: Yiwu Jingsourcing Ecommerce Co Limited, Yiwu, Zhejiang, CN | B32: 9603909900 | C32: Ždímací mop s dvoukomorovým kbelíkem | D32: CN | E32: =SUMIF(Položky!$B$4:$B$63,$B32,Položky!G$4:G$63) -> 100 | F32: =ROUND(SUMIF(Položky!$B$4:$B$63,$B32,Položky!K$4:K$63),3) -> 170 | G32: =ROUND(SUMIF(Položky!$B$4:$B$63,$B32,Položky!L$4:L$63),3) -> 180 | H32: =ROUND(SUMIF(Položky!$B$4:$B$63,$B32,Položky!N$4:N$63),2) -> 595.5 | I32: =ROUND(H32*$C$55,2) -> 553.71 | J32: FOB Ningbo
A33: Yiwu Jingsourcing Ecommerce Co Limited, Yiwu, Zhejiang, CN | B33: 3924900090 | C33: Podtácek sněhová vločka - stříbrná | D33: CN | E33: =SUMIF(Položky!$B$4:$B$63,$B33,Položky!G$4:G$63) -> 3600 | F33: =ROUND(SUMIF(Položky!$B$4:$B$63,$B33,Položky!K$4:K$63),3) -> 28.8 | G33: =ROUND(SUMIF(Položky!$B$4:$B$63,$B33,Položky!L$4:L$63),3) -> 30.6 | H33: =ROUND(SUMIF(Položky!$B$4:$B$63,$B33,Položky!N$4:N$63),2) -> 594 | I33: =ROUND(H33*$C$55,2) -> 552.32 | J33: FOB Ningbo
A34: Yiwu Jingsourcing Ecommerce Co Limited, Yiwu, Zhejiang, CN | B34: 9503003500 | C34: Vozík se stavebnicí pro děti | D34: CN | E34: =SUMIF(Položky!$B$4:$B$63,$B34,Položky!G$4:G$63) -> 96 | F34: =ROUND(SUMIF(Položky!$B$4:$B$63,$B34,Položky!K$4:K$63),3) -> 120 | G34: =ROUND(SUMIF(Položky!$B$4:$B$63,$B34,Položky!L$4:L$63),3) -> 132 | H34: =ROUND(SUMIF(Položky!$B$4:$B$63,$B34,Položky!N$4:N$63),2) -> 523.6 | I34: =ROUND(H34*$C$55,2) -> 486.86 | J34: FOB Ningbo
A35: Yiwu Jingsourcing Ecommerce Co Limited, Yiwu, Zhejiang, CN | B35: 8205510000 | C35: Otvírák s počítadlem | D35: CN | E35: =SUMIF(Položky!$B$4:$B$63,$B35,Položky!G$4:G$63) -> 400 | F35: =ROUND(SUMIF(Položky!$B$4:$B$63,$B35,Položky!K$4:K$63),3) -> 14.8 | G35: =ROUND(SUMIF(Položky!$B$4:$B$63,$B35,Položky!L$4:L$63),3) -> 16 | H35: =ROUND(SUMIF(Položky!$B$4:$B$63,$B35,Položky!N$4:N$63),2) -> 505.6 | I35: =ROUND(H35*$C$55,2) -> 470.12 | J35: FOB Ningbo
A36: Yiwu Jingsourcing Ecommerce Co Limited, Yiwu, Zhejiang, CN | B36: 6216000000 | C36: Kuchyňská chňapka - kočičí tlapka | D36: CN | E36: =SUMIF(Položky!$B$4:$B$63,$B36,Položky!G$4:G$63) -> 300 | F36: =ROUND(SUMIF(Položky!$B$4:$B$63,$B36,Položky!K$4:K$63),3) -> 24 | G36: =ROUND(SUMIF(Položky!$B$4:$B$63,$B36,Položky!L$4:L$63),3) -> 27 | H36: =ROUND(SUMIF(Položky!$B$4:$B$63,$B36,Položky!N$4:N$63),2) -> 498 | I36: =ROUND(H36*$C$55,2) -> 463.06 | J36: FOB Ningbo | K36: K OVĚŘENÍ | L36: Doplňková jednotka u rukavic je obvykle PÁR. V dokladech není uvedeno, zda 300 ks = 300 párů, nebo 300 jednotlivých kusů. OVĚŘIT u dodavatele.
A37: Yiwu Jingsourcing Ecommerce Co Limited, Yiwu, Zhejiang, CN | B37: 9612200000 | C37: Sada na otisk tlapky - malá | D37: CN | E37: =SUMIF(Položky!$B$4:$B$63,$B37,Položky!G$4:G$63) -> 960 | F37: =ROUND(SUMIF(Položky!$B$4:$B$63,$B37,Položky!K$4:K$63),3) -> 32.64 | G37: =ROUND(SUMIF(Položky!$B$4:$B$63,$B37,Položky!L$4:L$63),3) -> 36 | H37: =ROUND(SUMIF(Položky!$B$4:$B$63,$B37,Položky!N$4:N$63),2) -> 482.9 | I37: =ROUND(H37*$C$55,2) -> 449.01 | J37: FOB Ningbo
A38: Yiwu Jingsourcing Ecommerce Co Limited, Yiwu, Zhejiang, CN | B38: 4911910090 | C38: Vánoční samolepky 500 ks - veselí sněhuláci | D38: CN | E38: =SUMIF(Položky!$B$4:$B$63,$B38,Položky!G$4:G$63) -> 1400 | F38: =ROUND(SUMIF(Položky!$B$4:$B$63,$B38,Položky!K$4:K$63),3) -> 63 | G38: =ROUND(SUMIF(Položky!$B$4:$B$63,$B38,Položky!L$4:L$63),3) -> 70 | H38: =ROUND(SUMIF(Položky!$B$4:$B$63,$B38,Položky!N$4:N$63),2) -> 389.2 | I38: =ROUND(H38*$C$55,2) -> 361.89 | J38: FOB Ningbo
A39: Yiwu Jingsourcing Ecommerce Co Limited, Yiwu, Zhejiang, CN | B39: 3919108090 | C39: Nalepovací těsnění do oken a dveří 1 m | D39: CN | E39: =SUMIF(Položky!$B$4:$B$63,$B39,Položky!G$4:G$63) -> 2000 | F39: =ROUND(SUMIF(Položky!$B$4:$B$63,$B39,Položky!K$4:K$63),3) -> 36 | G39: =ROUND(SUMIF(Položky!$B$4:$B$63,$B39,Položky!L$4:L$63),3) -> 38 | H39: =ROUND(SUMIF(Položky!$B$4:$B$63,$B39,Položky!N$4:N$63),2) -> 380 | I39: =ROUND(H39*$C$55,2) -> 353.34 | J39: FOB Ningbo
A40: Yiwu Jingsourcing Ecommerce Co Limited, Yiwu, Zhejiang, CN | B40: 6307901000 | C40: Vánoční spona na závěs - sněhulák | D40: CN | E40: =SUMIF(Položky!$B$4:$B$63,$B40,Položky!G$4:G$63) -> 200 | F40: =ROUND(SUMIF(Položky!$B$4:$B$63,$B40,Položky!K$4:K$63),3) -> 24 | G40: =ROUND(SUMIF(Položky!$B$4:$B$63,$B40,Položky!L$4:L$63),3) -> 26 | H40: =ROUND(SUMIF(Položky!$B$4:$B$63,$B40,Položky!N$4:N$63),2) -> 367 | I40: =ROUND(H40*$C$55,2) -> 341.25 | J40: FOB Ningbo
A41: Yiwu Jingsourcing Ecommerce Co Limited, Yiwu, Zhejiang, CN | B41: 3919908099 | C41: Bílé vánoční samolepky na okno - zasněžená krajina | D41: CN | E41: =SUMIF(Položky!$B$4:$B$63,$B41,Položky!G$4:G$63) -> 420 | F41: =ROUND(SUMIF(Položky!$B$4:$B$63,$B41,Položky!K$4:K$63),3) -> 42 | G41: =ROUND(SUMIF(Položky!$B$4:$B$63,$B41,Položky!L$4:L$63),3) -> 45 | H41: =ROUND(SUMIF(Položky!$B$4:$B$63,$B41,Položky!N$4:N$63),2) -> 302.4 | I41: =ROUND(H41*$C$55,2) -> 281.18 | J41: FOB Ningbo
...

Sheet Sheet

Sheet Položky
A1: Rozpad jednotlivých položek – faktura JW20260707P11 / Packing List P11 (60 řádků)
A3: Č. položky | B3: HS kód | C3: Název (EN) | D3: Popis (CZ) | E3: Celní popis (CZ) | F3: Materiál | G3: Množství (ks) | H3: Kartonů | I3: Čistá hmotnost (kg/ks) | J3: Zdroj čisté hm. | K3: Čistá hmotnost (kg) | L3: Hrubá hmotnost (kg) | M3: Jedn. cena USD | N3: Hodnota USD – před slevou | O3: Hodnota USD – po slevě | P3: Poznámka
A4: 1 | B4: 9405423990 | C4: Micro LED Christmas Star Silhouette 30 cm | D4: Vánoční LED kovová hvězda | E4: Svítíce dekorace do interiéru. | F4: Železo a měděný drát | G4: 400 | H4: 10 | I4: 0.125 | J4: dodavatel | K4: =ROUND(G4*I4,3) -> 50 | L4: 60 | M4: 2.809 | N4: 1123.6 | O4: =ROUND(N4*'HS Summary'!$C$55,2) -> 1044.76
A5: 2 | B5: 8205510000 | C5: Counting bootle opener | D5: Otvírák s počítadlem | E5: Otvírák, který ukazuje počet otevřených láhví. | F5: kov, plast | G5: 400 | H5: 2 | I5: 0.037 | J5: dodavatel | K5: =ROUND(G5*I5,3) -> 14.8 | L5: 16 | M5: 1.264 | N5: 505.6 | O5: =ROUND(N5*'HS Summary'!$C$55,2) -> 470.12
A6: 3 | B6: 9503009990 | C6: Magnet Dress Up Doll Puzzle Box | D6: Dětská magnetická hra v kufříku oblékání panenek | E6: Sada magnetických obrázků. Lze na hrací desce oblákat panenky. V balení také ilustrační obrázky. Hračka pro děti. | G6: 180 | H6: 5 | I6: 0.722 | J6: dodavatel | K6: =ROUND(G6*I6,3) -> 129.96 | L6: 135 | M6: 3.77 | N6: 678.6 | O6: =ROUND(N6*'HS Summary'!$C$55,2) -> 630.98
A7: 4 | B7: 7009920000 | C7: Mini LED makeup mirror | D7: Cestovní kosmetické zrcátko s podsvícením | E7: Malé zrcátko do kapsy s podsvícením. Napájení na baterie. | F7: ABS, PE, Sklo | G7: 600 | H7: 6 | I7: 0.0853 | J7: dopočteno | K7: =ROUND(G7*I7,3) -> 51.18 | L7: 54 | M7: 2.562 | N7: 1537.2 | O7: =ROUND(N7*'HS Summary'!$C$55,2) -> 1429.33 | P7: Dodavatel uvedl 0,120 kg/ks, ale hrubá váha je jen 0,090 kg/ks – čistá nemůže být vyšší než hrubá. Dopočteno poměrem 0,948034 z hrubé váhy. VYŽÁDAT OPRAVU.
A8: 5 | B8: 3924900090 | C8: Snowflake Cup Coaster - silver | D8: Podtácek sněhová vločka - stříbrná | E8: Tácek pod nápoje. | F8: PVC | G8: 3600 | H8: 2 | I8: 0.008 | J8: dodavatel | K8: =ROUND(G8*I8,3) -> 28.8 | L8: 30.6 | M8: 0.165 | N8: 594 | O8: =ROUND(N8*'HS Summary'!$C$55,2) -> 552.32
A9: 6 | B9: 3406000000 | C9: Magic candle - cylinder | D9: Kouzelná svíčka | E9: Dekorační svíčka, která při rozsvícení zaktivuje LED světlo, které pak svítí do sfouknutí ohně. LED světlo se aktivuje pomocí čidla na světlo. Svíčka slouží k dekoračním účelům. | F9: LED světlo a vosk | G9: 4464 | H9: 62 | I9: 0.1448 | J9: dopočteno | K9: =ROUND(G9*I9,3) -> 646.387 | L9: 682 | M9: 1.36 | N9: 6071 | O9: =ROUND(N9*'HS Summary'!$C$55,2) -> 5644.99 | P9: Dodavatel uvedl 0,181 kg/ks, ale hrubá váha je jen 0,153 kg/ks – čistá nemůže být vyšší než hrubá. (Srovnej svíčky č. 7 = 0,111 a č. 8 = 0,194.) Dopočteno poměrem 0,948034 z hrubé váhy. VYŽÁDAT OPRAVU.
A10: 7 | B10: 3406000000 | C10: Magic candle - pyramid | D10: Kouzelná svíčka - čtyřstěnná pyramida | E10: Dekorační svíčka, která při rozsvícení zaktivuje LED světlo, které pak svítí do sfouknutí ohně. LED světlo se aktivuje pomocí čidla na světlo. Svíčka slouží k dekoračním účelům. | F10: LED světlo a vosk | G10: 3600 | H10: 50 | I10: 0.111 | J10: dodavatel | K10: =ROUND(G10*I10,3) -> 399.6 | L10: 450 | M10: 1.38 | N10: 4968 | O10: =ROUND(N10*'HS Summary'!$C$55,2) -> 4619.39
A11: 8 | B11: 3406000000 | C11: Magic candle - heart | D11: Kouzelná svíčka - srdce | E11: Dekorační svíčka, která při rozsvícení zaktivuje LED světlo, které pak svítí do sfouknutí ohně. LED světlo se aktivuje pomocí čidla na světlo. Svíčka slouží k dekoračním účelům. | F11: LED světlo a vosk | G11: 1080 | H11: 15 | I11: 0.194 | J11: dodavatel | K11: =ROUND(G11*I11,3) -> 209.52 | L11: 225 | M11: 1.28 | N11: 1382.4 | O11: =ROUND(N11*'HS Summary'!$C$55,2) -> 1285.4
A12: 9 | B12: 9503006900 | C12: IQ Puzzle 3D Challenge Game PRO | D12: IQ Puzzle 3D | E12: Logická 3D kuličková hra pro děti. | F12: ABS | G12: 4200 | H12: 42 | I12: 0.0474 | J12: dopočteno | K12: =ROUND(G12*I12,3) -> 199.08 | L12: 210 | M12: 1.071 | N12: 4498.2 | O12: =ROUND(N12*'HS Summary'!$C$55,2) -> 4182.56 | P12: Dodavatel uvedl ZÁPORNOU hodnotu −0,010 kg/ks. Dopočteno poměrem 0,948034 z hrubé váhy. VYŽÁDAT OPRAVU.
A13: 10 | B13: 6302329000 | C13: Microplush sheet 90x200 - dark grey | D13: Mikroplyšové prostěradlo 90 x 200 cm - tmavě šedé | E13: Ložní prádlo. | F13: 100% polyester | G13: 200 | H13: 2 | I13: 0.367 | J13: dodavatel | K13: =ROUND(G13*I13,3) -> 73.4 | L13: 75 | M13: 3.659 | N13: 731.8 | O13: =ROUND(N13*'HS Summary'!$C$55,2) -> 680.45
A14: 11 | B14: 9404909000 | C14: Pillow with legs | D14: Polštář s nožičkami - fotbalový míč | E14: Polštářek s roztomilým designem. | F14: 100% polyester | G14: 1600 | H14: 10 | I14: 0.369 | J14: dodavatel | K14: =ROUND(G14*I14,3) -> 590.4 | L14: 600 | M14: 2.194 | N14: 3510.4 | O14: =ROUND(N14*'HS Summary'!$C$55,2) -> 3264.07
A15: 12 | B15: 9503007590 | C15: 2 in 1 Electric RC Car Transformation Robots - red | D15: RC Sportovní transformující se autíčko na dálkové ovládání - červené | E15: Elektrické autíčko na ovládání, které se může proměnit v robota. | F15: ABS | G15: 1728 | H15: 36 | I15: 0.375 | J15: dodavatel | K15: =ROUND(G15*I15,3) -> 648 | L15: 684 | M15: 2.92 | N15: 5045.8 | O15: =ROUND(N15*'HS Summary'!$C$55,2) -> 4691.73
A16: 13 | B16: 9506999000 | C16: Sway Insect | D16: Tančící housenka | E16: Cílem hry je házet kroužky na hlavu housenky. Housenka se po zapnutí hýbe do stran. | F16: ABS, el. součásti | G16: 180 | H16: 5 | I16: 0.722 | J16: dodavatel | K16: =ROUND(G16*I16,3) -> 129.96 | L16: 135 | M16: 3.9 | N16: 702 | O16: =ROUND(N16*'HS Summary'!$C$55,2) -> 652.74
A17: 14 | B17: 9503007590 | C17: Automatic Domino Train Toy | D17: Vláček stavějící domino | E17: Vláček, který skládá domino. Také přehrává melodii. Hračka pro děti. | F17: ABS, elektro součástky | G17: 1632 | H17: 34 | I17: 0.521 | J17: dodavatel | K17: =ROUND(G17*I17,3) -> 850.272 | L17: 884 | M17: 3.034 | N17: 4951.5 | O17: =ROUND(N17*'HS Summary'!$C$55,2) -> 4604.05
A18: 15 | B18: 9503009590 | C18: Fantastic Drawing Magic Pad | D18: Kouzelné kreslení | E18: Tabulka má podsvícení, díky kterému fixami namalované obrázky na tabulce svítí. Hračka pro děti. | F18: ABS, papír, PP, akrylát | G18: 3000 | H18: 25 | I18: 0.325 | J18: dodavatel | K18: =ROUND(G18*I18,3) -> 975 | L18: 1000 | M18: 1.773 | N18: 5319 | O18: =ROUND(N18*'HS Summary'!$C$55,2) -> 4945.76
A19: 16 | B19: 9503004990 | C19: Baby Bath Toys Fun Foam Animals | D19: Pěnová zvířátka do vany 15 ks | E19: Hračka pro děti. Vhodné do vany. | F19: PE | G19: 150 | H19: 1 | I19: 0.04 | J19: dodavatel | K19: =ROUND(G19*I19,3) -> 6 | L19: 7 | M19: 1.574 | N19: 236.1 | O19: =ROUND(N19*'HS Summary'!$C$55,2) -> 219.53
A20: 17 | B20: 9503007590 | C20: 3 in 1 Solarbot Dinosaur Robot | D20: Solarbot 3v1 | E20: Solární stavebnice pro děti. | F20: plast, základní deska | G20: 360 | H20: 5 | I20: 0.278 | J20: dodavatel | K20: =ROUND(G20*I20,3) -> 100.08 | L20: 105 | M20: 2.66 | N20: 957.6 | O20: =ROUND(N20*'HS Summary'!$C$55,2) -> 890.4
A21: 18 | B21: 9503007000 | C21: Fantasy Hand-Painted dress-up princess | D21: Textilní tvoření pro princezny | E21: Tvořivá sada pro děti - papírové princezny s látkovými kousky. | F21: Papír, polyester | G21: 1440 | H21: 8 | I21: 0.089 | J21: dodavatel | K21: =ROUND(G21*I21,3) -> 128.16 | L21: 136 | M21: 1.061 | N21: 1527.8 | O21: =ROUND(N21*'HS Summary'!$C$55,2) -> 1420.59
A22: 19 | B22: 6308000020 | C22: Embroidery For Kids - unicorn with rainbow | D22: Vyšívání pro děti - jednorožec | E22: Sada pro vyšívání. V balení rám, nitě a vyšívací nástroje. Hračka pro děti. | F22: Polyester, ABS, Ocel | G22: 360 | H22: 3 | I22: 0.083 | J22: dodavatel | K22: =ROUND(G22*I22,3) -> 29.88 | L22: 33 | M22: 2.005 | N22: 721.8 | O22: =ROUND(N22*'HS Summary'!$C$55,2) -> 671.15
A23: 20 | B23: 9615900000 | C23: Hair Glowing Luminescent Hairpin | D23: Svítící klip do vlasů - motýlek | E23: Ozdoba do vlasů se sponkou ve tvaru motýla se zabudovaným LED světlem, které mění barvu. Hračka pro děti. | F23: ABS, LED diody | G23: 600 | H23: 1 | I23: 0.015 | J23: dodavatel | K23: =ROUND(G23*I23,3) -> 9 | L23: 10 | M23: 0.283 | N23: 169.8 | O23: =ROUND(N23*'HS Summary'!$C$55,2) -> 157.89
A24: 21 | B24: 7117900000 | C24: Rhinestone Applicator Extra Box of Stones | D24: Náhradní kamínky k aplikátoru | E24: Náhradní kamínky do aplikátoru na lepení kamínků, cca 2000ks kamínků, váha 55g. | F24: papír, sklo | G24: 200 | H24: 1 | I24: 0.045 | J24: dodavatel | K24: =ROUND(G24*I24,3) -> 9 | L24: 10 | M24: 1.132 | N24: 226.4 | O24: =ROUND(N24*'HS Summary'!$C$55,2) -> 210.51
... A44: 41 | B44: 6306220000 | C44: Kids tent | D44: Dětský stan vesmírná raketa | E44: Stan do interiéru. Hračka pro děti. | F44: 100% polyester | G44: 120 | H44: 4 | I44: 0.767 | J44: dodavatel | K44: =ROUND(G44*I44,3) -> 92.04 | L44: 96 | M44: 7.55 | N44: 906 | O44: =ROUND(N44*'HS Summary'!$C$55,2) -> 842.43
A45: 42 | B45: 9603909900 | C45: Flat Floor Mop and Bucket Set with Aluminum Handle | D45: Ždímací mop s dvoukomorovým kbelíkem | E45: Pomůcka pro vytírání podlahy. Mop + kyblík v balení. | G45: 100 | H45: 10 | I45: 1.7 | J45: dodavatel | K45: =ROUND(G45*I45,3) -> 170 | L45: 180 | M45: 5.955 | N45: 595.5 | O45: =ROUND(N45*'HS Summary'!$C$55,2) -> 553.71
A46: 43 | B46: 9403700000 | C46: Decorative sutterfly wall shelf | D46: Polička na zeď - motýl | E46: Plastová polička se vzhledem motýla. Součástí balení jsou nabíjecí háčky. | F46: PVC | G46: 160 | H46: 4 | I46: 0.4 | J46: dodavatel | K46: =ROUND(G46*I46,3) -> 64 | L46: 68 | M46: 1.025 | N46: 164 | O46: =ROUND(N46*'HS Summary'!$C$55,2) -> 152.49
A47: 44 | B47: 9503007000 | C47: Find Location Games | D47: Didaktická hra se zvířátky - Prostorové vnímání | E47: Hra na prostorové vnímání. Součástí balení je 20 ks obrázků se zvířátky, pomocí žetonů s obrázky daných zvířátek se určuje kde se jaké nachází (před, za, na, uvnitř, ..), na druhé straně obrázku je řešení. Hračka pro děti. | F47: Dřevo, papír | G47: 120 | H47: 3 | I47: 0.25 | J47: dodavatel | K47: =ROUND(G47*I47,3) -> 30 | L47: 33 | M47: 2.88 | N47: 345.6 | O47: =ROUND(N47*'HS Summary'!$C$55,2) -> 321.35
A48: 45 | B48: 8543709099 | C48: Rhinestone Applicator B | D48: Aplikátor na lepení kamínků + sada kamínků | E48: Aplikátor určený ke zdobení textilu a textilních výrobků. Kamínky se poskládají do požadavaného tvaru a pomocí přístroje se několik vteřin přidrží na vybraném místě. Balení obsahuje aplikátor, krabička s kamínky, látková taštička, 7x nástavec na přilepení kamínků (různé průměry), 1x stojánek, 2x mistička, 2x tužka,1x kartáček, 1x pinzeta, 1x pytlíček. Balení obsahuje kamínky o jedné velikosti v různých barevných provedeních. | F48: ABS, El. součástky, kov, PVC, PP | G48: 150 | H48: 3 | I48: 0.26 | J48: dodavatel | K48: =ROUND(G48*I48,3) -> 39 | L48: 42 | M48: 4.304 | N48: 645.6 | O48: =ROUND(N48*'HS Summary'!$C$55,2) -> 600.3
A49: 46 | B49: 9405423100 | C49: Voice controlr rhythm ligh- black | D49: LED světelný panel reagující na zvuk - černý | E49: Světelná dekorace k počítači. Panel reaguje na světlo promítanými barvami. | F49: ABS, PVC | G49: 400 | H49: 4 | I49: 0.06 | J49: dodavatel | K49: =ROUND(G49*I49,3) -> 24 | L49: 28 | M49: 1.55 | N49: 620 | O49: =ROUND(N49*'HS Summary'!$C$55,2) -> 576.49
A50: 47 | B50: 9615190000 | C50: Kids Set Of Hair Accessories | D50: Velká sada ozdob do vlasů | E50: Dětská sada gumiček a sponek. Baleno v dárkové krabičce. | F50: Pryž, polyester, Ocel, PP | G50: 1500 | H50: 7 | I50: 0.126 | J50: dodavatel | K50: =ROUND(G50*I50,3) -> 189 | L50: 196.262 | M50: 0.917 | N50: 1375.5 | O50: =ROUND(N50*'HS Summary'!$C$55,2) -> 1278.98
A51: 48 | B51: 9405423990 | C51: Enchanted Galaxy Rose in a Glass Dome | D51: Elegantní svítící růže ve skleněné váze | E51: Dekorace. Růže ve skle s LED svítícím řetězem. | G51: 504 | H51: 21 | I51: 0.333 | J51: dodavatel | K51: =ROUND(G51*I51,3) -> 167.832 | L51: 189 | M51: 1.571 | N51: 791.8 | O51: =ROUND(N51*'HS Summary'!$C$55,2) -> 736.24
A52: 49 | B52: 3926100000 | C52: A4 file storage box | D52: Uzavíratelný pořadač na dokumenty | E52: Pomocník pro organizaci dokumentů. | F52: PET | G52: 420 | H52: 7 | I52: 0.167 | J52: dodavatel | K52: =ROUND(G52*I52,3) -> 70.14 | L52: 77 | M52: 0.637 | N52: 267.5 | O52: =ROUND(N52*'HS Summary'!$C$55,2) -> 248.73
A53: 50 | B53: 9503009590 | C53: Mini Basketball | D53: Basketbalový koš na dveře - sada s míčkem a pumpičkou | E53: Hračka pro děti. Balení obsahuje míček, pumpičku a koš na zavěšení. | G53: 168 | H53: 1 | I53: 0.167 | J53: dodavatel | K53: =ROUND(G53*I53,3) -> 28.056 | L53: 29 | M53: 0.857 | N53: 144 | O53: =ROUND(N53*'HS Summary'!$C$55,2) -> 133.9
A54: 51 | B54: 9503007000 | C54: Christmas Magic Scratch Painting Set | D54: Velká vyškrabávací sada s vánočními motivy | E54: Sada vyškrabávacích ozdob pro děti na Vánoce. Hračka pro děti. | F54: Papír, polyester, dřevo | G54: 500 | H54: 3 | I54: 0.061 | J54: dodavatel | K54: =ROUND(G54*I54,3) -> 30.5 | L54: 33.333 | M54: 0.727 | N54: 363.5 | O54: =ROUND(N54*'HS Summary'!$C$55,2) -> 337.99
A55: 52 | B55: 9503003500 | C55: Pipe Building Blocks | D55: Vozík se stavebnicí pro děti | E55: Stavebnice tvořená trubičkami, které lze spojovat do tvarů. Hračka pro děti. | F55: ABS | G55: 96 | H55: 12 | I55: 1.25 | J55: dodavatel | K55: =ROUND(G55*I55,3) -> 120 | L55: 132 | M55: 5.454 | N55: 523.6 | O55: =ROUND(N55*'HS Summary'!$C$55,2) -> 486.86
A56: 53 | B56: 3919908099 | C56: Christmas Window Stickers Snow Woods - snowman (BJC813) | D56: Bílé vánoční samolepky na okno - zasněžená krajina | E56: Dekorativní samolepka na okno. | F56: PVC | G56: 420 | H56: 3 | I56: 0.1 | J56: dodavatel | K56: =ROUND(G56*I56,3) -> 42 | L56: 45 | M56: 0.72 | N56: 302.4 | O56: =ROUND(N56*'HS Summary'!$C$55,2) -> 281.18
A57: 54 | B57: 9503006900 | C57: Puzzle Book | D57: Puzzle pro děti - zvířátka | E57: Puzzle zvířátka z tvrdého papíru s kvalitním potiskem. Každé zvířátko se skládá vždy ze dvou kusů. Z druhé strany je anglický název zvířete. Celkem 24 zvířátek (např. ježek, medvěd, včela, želva, králík atd.). Slouží jako hračka pro děti. | F57: Lepený papír | G57: 120 | H57: 2 | I57: 0.35 | J57: dodavatel | K57: =ROUND(G57*I57,3) -> 42 | L57: 44 | M57: 1.7 | N57: 204 | O57: =ROUND(N57*'HS Summary'!$C$55,2) -> 189.69
A58: 55 | B58: 9612200000 | C58: Pets Footprints | D58: Sada na otisk tlapky - malá | E58: Balení obsahuje otiskovací část a 2 kartičky. Tlapička se přitiskne na fólii a ta se otiskne na papírek. | F58: Papír, PVC fólie, razítková podložka, razítková barva | G58: 960 | H58: 3 | I58: 0.034 | J58: dodavatel | K58: =ROUND(G58*I58,3) -> 32.64 | L58: 36 | M58: 0.503 | N58: 482.9 | O58: =ROUND(N58*'HS Summary'!$C$55,2) -> 449.01
A59: 56 | B59: 7013499900 | C59: 360 Rotating spice storage | D59: Otočný stojan se skleněnými kořenkami 18 ks | E59: Otočný stojan na kořenky. Doplněk do kuchyně. Balení obsahuje 18 otočných kořenek. | F59: ABS, PP, Sklo | G59: 144 | H59: 12 | I59: 2.417 | J59: dodavatel | K59: =ROUND(G59*I59,3) -> 348.048 | L59: 360 | M59: 4.446 | N59: 640.2 | O59: =ROUND(N59*'HS Summary'!$C$55,2) -> 595.28
A60: 57 | B60: 9503005590 | C60: Dancing Xmas tree - sing | D60: Tančící vánoční stromeček - zpívající | E60: Vánoční hračka - zpívá a hýbá se. | F60: potah: 100% nylon | G60: 900 | H60: 18 | I60: 0.4 | J60: dodavatel | K60: =ROUND(G60*I60,3) -> 360 | L60: 378 | M60: 4.28 | N60: 3852 | O60: =ROUND(N60*'HS Summary'!$C$55,2) -> 3581.7
...

Sheet Dokumenty a poznámky
A1: 4Leaders, s.r.o. – zásilka 2026P11 – poznámky k celnímu odbavení
A3: 🟠 ČISTÁ HMOTNOST – 3 CHYBNÉ HODNOTY OD DODAVATELE (VYŽÁDAT OPRAVU)
A4: Dodavatel doplnil čistou hmotnost na kus do revidovaného packing listu (soubor „Packing list-P11net weight.xlsx“, sloupec „gross weight / each product / kg“).
A5: 57 z 60 položek je v pořádku a je použito tak, jak je dodavatel uvedl. U 3 položek je hodnota fyzikálně nemožná:
A7: • Položka 4 – Mini LED makeup mirror: uvedeno 0,120 kg/ks, ale hrubá hmotnost je jen 0,090 kg/ks (9 kg ÷ 100 ks v kartonu). Čistá nemůže být vyšší než hrubá.
A8: • Položka 6 – Magic candle - cylinder: uvedeno 0,181 kg/ks, ale hrubá hmotnost je jen 0,153 kg/ks (11 kg ÷ 72 ks). Pro srovnání sesterské svíčky: č. 7 = 0,111 kg/ks, č. 8 = 0,194 kg/ks.
A9: • Položka 9 – IQ Puzzle 3D Challenge Game PRO: uvedena ZÁPORNÁ hodnota −0,010 kg/ks.
A11: ŘEŠENÍ POUŽITÉ V TOMTO SOUHRNU: u těchto 3 položek je čistá hmotnost dopočtena jako hrubá hmotnost × 0,948034.
A12: Poměr 0,948034 = součet čistých / součet hrubých hmotností z 57 platných řádků. Dopočtené položky jsou v listu „Položky“ oranžově a ve sloupci „Zdroj čisté hm.“ označeny jako „dopočteno“.
A13: Dopočtené hodnoty: položka 4 = 51,18 kg (0,0853 kg/ks), položka 6 = 646,39 kg (0,1448 kg/ks), položka 9 = 199,08 kg (0,0474 kg/ks).
A15: → VYŽÁDAT U DODAVATELE OPRAVU těchto 3 hodnot. Do té doby jsou v JSD použity dopočtené údaje.
A17: Čistá hmotnost – celkový součet a co číslo zřejmě obsahuje
... A92: • reference/CBAM_receivers_CZ.xlsx – registr CBAM příjemců v ČR (příjemce nenalezen).
