Workbook

Sheet Souhrn HS
A1: SOUHRN HS KÓDŮ – Kovář, zásilka 576188
A2: Dvě celní prohlášení: JSD 1 (běžné) a JSD 2 (FOC – HS 4016 93 00 90)
A4: Klient / příjemce | B4: STUDNAŘSTVÍ KOVÁŘ s.r.o., Jaurisova 515/4, Michle (Praha 4), 140 00 Praha – EORI CZ29153824
A5: Odesílatel (dodavatel) | B5: HENAN RANCHENG MACHINERY CO., LTD, No. 33 Jinsuo Road, High-tech zone, Zhengzhou, Henan, Čína
A6: Číslo zásilky / reference | B6: 576188 (OR / CZ26008893)
A7: Faktura | B7: RCJX-2026041605A ze dne 14.05.2026
A8: B/L | B8: PDYWM2605186 (Telex release), plavidlo MSC NAPOLI GL621W, Qingdao → Praha
A9: Předchozí doklad (T1) | B9: MRN 26DE245296473362J8, Bremerhaven → Praha Uhříněves (A1-TRANSPORT&LOGISTIC, CFS „CPS“)
A10: Dodací doložka (Incoterm) | B10: CIF Praha (dle faktury a packing listu; pojistka DIC kryje trasu Qingdao → Praha)
A11: Země původu | B11: Čína (CN) – MADE IN CHINA
A12: Měna | B12: USD
A13: Počet kusů / balení | B13: 2 balení (PACKAGE NO. 1/2, 2/2), 0,62 CBM
A14: Hrubá hmotnost celkem | B14: 290 kg
A15: Čistá hmotnost celkem | B15: 260 kg
A17: VSTUPY / PŘEDPOKLADY (modré = zadané hodnoty, žluté = k potvrzení)
A18: Čistá hmotnost celkem dle packing listu (kg) | B18: 260 | C18: Packing list RCJX-2026041605A: NET WEIGHT 260 KGS
A19: Hrubá hmotnost celkem dle packing listu (kg) | B19: 290 | C19: Packing list RCJX-2026041605A: GROSS WEIGHT 290 KGS
A20: Odhad čisté hmotnosti FOC těsnění (kg) | B20: 0.1 | C20: Odhad Karla Fleyberka v e-mailu 12.05.2026: „To bude tak 10 dkg“ = cca 0,1 kg. K POTVRZENÍ.
A21: Deklarovaná celní hodnota FOC položky (USD) | B21: 1 | C21: Pokyn příjemce přes Kamilu Levovou 30.06.2026: „pokud to nepůjde jinak dejte tam částku 1 dolar (toto zboží je zdarma)“.
A22: Náklady na dopravu v ceně faktury (USD) | B22: ='Rozpad ceny'!G13 | C22: Přebírá se z listu Rozpad ceny.
A24: JSD 1 – BĚŽNÉ CELNÍ PROHLÁŠENÍ
A25: Odesílatel | B25: HS kód | C25: Popis (CZ) | D25: Množství | E25: Čistá hm. (kg) | F25: Hrubá hm. (kg) | G25: Cena zboží (USD) | H25: Podíl dopravy (USD) | I25: Celní hodnota (USD) | J25: CBAM | K25: Antidumping
A26: Henan Rancheng Machinery Co., Ltd | B26: 8431 43 00 90 | C26: Části a součásti vrtacích nebo hloubicích strojů – vrtná hlava, integrované ovládání hlavy (rychloventil), adaptéry / ocel | D26: =SUMIFS('Rozpad ceny'!$D$6:$D$11,'Rozpad ceny'!$H$6:$H$11,$B26) | E26: =ROUND(($B$18-$B$20)*$G26/SUM($G$26:$G$28),3) | F26: =ROUND(($B$19-$B$20)*$G26/SUM($G$26:$G$28),3) | G26: =SUMIFS('Rozpad ceny'!$G$6:$G$11,'Rozpad ceny'!$H$6:$H$11,$B26) | H26: =ROUND($B$22*$G26/SUM($G$26:$G$28),2) | I26: =$G26+$H26 | J26: Ne | K26: Neuplatňuje se – prověřit v TARIC
A27: Henan Rancheng Machinery Co., Ltd | B27: 8207 19 90 00 | C27: Vyměnitelné nástroje na vrtání nebo sondáž při zemních pracích – reverzní kladivo, vnější průměr 220 mm / ocel | D27: =SUMIFS('Rozpad ceny'!$D$6:$D$11,'Rozpad ceny'!$H$6:$H$11,$B27) | E27: =ROUND(($B$18-$B$20)*$G27/SUM($G$26:$G$28),3) | F27: =ROUND(($B$19-$B$20)*$G27/SUM($G$26:$G$28),3) | G27: =SUMIFS('Rozpad ceny'!$G$6:$G$11,'Rozpad ceny'!$H$6:$H$11,$B27) | H27: =ROUND($B$22*$G27/SUM($G$26:$G$28),2) | I27: =$G27+$H27 | J27: Ne | K27: Neuplatňuje se – prověřit v TARIC
A28: Henan Rancheng Machinery Co., Ltd | B28: 8481 30 91 99 | C28: Zpětné ventily (klapky) z oceli | D28: =SUMIFS('Rozpad ceny'!$D$6:$D$11,'Rozpad ceny'!$H$6:$H$11,$B28) | E28: =ROUND(($B$18-$B$20)*$G28/SUM($G$26:$G$28),3) | F28: =ROUND(($B$19-$B$20)*$G28/SUM($G$26:$G$28),3) | G28: =SUMIFS('Rozpad ceny'!$G$6:$G$11,'Rozpad ceny'!$H$6:$H$11,$B28) | H28: =ROUND($B$22*$G28/SUM($G$26:$G$28),2) | I28: =$G28+$H28 | J28: Ne | K28: Neuplatňuje se – prověřit v TARIC
C29: JSD 1 CELKEM | D29: =SUM(D26:D28) | E29: =SUM(E26:E28) | F29: =SUM(F26:F28) | G29: =SUM(G26:G28) | H29: =SUM(H26:H28) | I29: =SUM(I26:I28)
A31: JSD 2 – FOC (zboží zdarma)
A32: Odesílatel | B32: HS kód | C32: Popis (CZ) | D32: Množství | E32: Čistá hm. (kg) | F32: Hrubá hm. (kg) | G32: Cena zboží (USD) | H32: Podíl dopravy (USD) | I32: Celní hodnota (USD) | J32: CBAM | K32: Antidumping
A33: Henan Rancheng Machinery Co., Ltd | B33: 4016 93 00 90 | C33: Plochá těsnění, podložky a jiná těsnění z vulkanizovaného kaučuku – sada těsnění k vrtné hlavě (FOC) | D33: =SUMIFS('Rozpad ceny'!$D$6:$D$11,'Rozpad ceny'!$H$6:$H$11,$B33) | E33: =$B$20 | F33: =$B$20 | G33: =SUMIFS('Rozpad ceny'!$G$6:$G$11,'Rozpad ceny'!$H$6:$H$11,$B33) | H33: 0 | I33: =$B$21 | J33: Ne | K33: Neuplatňuje se – prověřit v TARIC
C34: JSD 2 CELKEM | D34: =D33 | E34: =E33 | F34: =F33 | G34: =G33 | H34: =H33 | I34: =I33
A36: KONTROLA CELKOVÉ ČÁSTKY
A37: Zboží + doprava dle rozpadu (JSD 1) | D37: =I29
A38: FOC položka – fakturovaná hodnota (0 USD) | D38: =G33
A39: Celkem fakturovaná hodnota zásilky (USD) | D39: =I29+G33
A40: Obchodní faktura RCJX-2026041605A (USD) | D40: ='Rozpad ceny'!G15
A41: Rozdíl | D41: =(I29+G33)-'Rozpad ceny'!G15
A42: VÝSLEDEK KONTROLY | D42: =IF(ROUND(D41,2)=0,"OK – součet položek přesně odpovídá faktuře USD 3 960","NESOUHLASÍ – prověřit")
A43: Kontrolní součet pojistky (DIC): USD 4 356 = 110 % z USD 3 960 | D43: =ROUND('Rozpad ceny'!G15*1.1,2)
A45: DŮLEŽITÉ POZNÁMKY
A46: PREFERENČNÍ PŮVOD – preferenční věta NENALEZENA | B46: V obchodní faktuře, packing listu ani v e-mailové komunikaci NENÍ uvedena preferenční věta (prohlášení o preferenčním původu). Země původu je Čína – EU nemá s Čínou preferenční dohodu, preferenční sazba tedy nepřichází v úvahu. Uplatní se standardní třetizemní (erga omnes) celní sazba. Sazby ověřit v TARIC k datu propuštění.
...

Sheet Rozpad ceny
A1: Rozpad fakturované částky na jednotlivé položky
A2: Kovář (Studnařství Kovář s.r.o.) / zásilka 576188 – faktura RCJX-2026041605A ze dne 14.05.2026
A3: Ceny nejsou na faktuře rozepsané (faktura zní na 1 SET / USD 3960). Rozpad níže je převzatý z e-mailové komunikace s dodavatelem (Tina, Henan Rancheng Machinery).
A5: # | B5: Položka dle faktury / e-mailu | C5: Popis (CZ) | D5: Množství | E5: MJ | F5: Jedn. cena (USD) | G5: Cena celkem (USD) | H5: HS kód | I5: JSD | J5: Zdroj ceny (e-mail)
A6: 1 | B6: Power head | C6: Vrtná hlava / ocel, pro vrtnou soupravu RCF260C, pro vrtné trubky prům. 89 mm, závit 76-series, připojení 2 3/8 REG | D6: 1 | E6: ks | F6: 2380 | G6: =D6*F6 | H6: 8431 43 00 90 | I6: JSD 1 – běžné | J6: Tina (Henan Rancheng): „USD2,380 (Power Head)“ / „2 380 USD (Hydraulická hlava)“
A7: 2 | B7: Quick fast valve | C7: Integrované ovládání vrtné hlavy, namontované přímo na hlavě, napojené na hydraulické vedení, určené jen k řízení otáček hydromotoru této hlavy | D7: 1 | E7: ks | F7: 400 | G7: =D7*F7 | H7: 8431 43 00 90 | I7: JSD 1 – běžné | J7: Tina: „USD400 (Quick Valve)“ / „400 USD (Rychloventil)“
A8: 3 | B8: Reverse-Acting Impactor 220 mm | C8: Reverzní kladivo – při průchodu vzduchu vytváří rázy směrem nahoru, aby se uvolnilo zaseknuté nářadí ze země / ocel | D8: 1 | E8: ks | F8: 730 | G8: =D8*F8 | H8: 8207 19 90 00 | I8: JSD 1 – běžné | J8: Tina: „USD730 (220mm OD Reverse Circulation Hammer)“; potvrzeno p. Kovářem: „Chtěl bych 220mm (730 usd)“
A9: 4 | B9: Check valves | C9: Zpětný ventil – klapka; propojení ve vrtné sestavě a zabránění zpětnému proudění vzduchu do hlavy / ocel | D9: 2 | E9: ks | F9: 50 | G9: =D9*F9 | H9: 8481 30 91 99 | I9: JSD 1 – běžné | J9: Tina: „USD100 (2 Check Valves)“ → 50 USD/ks
A10: 5 | B10: Adapter | C10: Prodloužení k vrtné hlavě, aby se opotřebovával vyměnitelný závit v adaptéru a ne závit v hlavě / ocel | D10: 2 | E10: ks | F10: 50 | G10: =D10*F10 | H10: 8431 43 00 90 | I10: JSD 1 – běžné | J10: Tina: „cena za dva adaptéry je 100 dolarů; cena za jeden adaptér je 50 dolarů … konečná částka se zvýšila na 3 960 dolarů“
A11: 6 | B11: One set accessories for power head | C11: Těsnění, aby netekl olej z hlavy (O-kroužky / gufera) – z vulkanizovaného kaučuku | D11: 1 | E11: sada | F11: 0 | G11: =D11*F11 | H11: 4016 93 00 90 | I11: JSD 2 – FOC | J11: Tina: „1 Set of Free Power Head Accessories“ – zdarma (FOC)
B12: Zboží celkem | G12: =SUM(G6:G11)
B13: Doprava (námořní LCL Qingdao → Praha) | C13: Náklady na dopravu zahrnuté v ceně na faktuře (dodací doložka CIF) | F13: 250 | G13: =F13 | I13: JSD 1 – běžné | J13: Tina: „USD250 (Shipping Cost)“ – „Ano, 250 USD pokrývá přepravu zboží přepravou LCL … do přístavu Praha“
B14: CELKEM dle rozpadu (USD) | G14: =G12+G13
B15: CELKEM dle obchodní faktury (USD) | G15: 3960
B16: KONTROLA (rozpad vs. faktura) | G16: =G14-G15 | H16: =IF(ROUND(G14-G15,2)=0,"OK – rozpad souhlasí s fakturou","NESOUHLASÍ – prověřit")
A18: Vývoj ceny v e-mailové komunikaci (doklad, jak se dospělo k částce 3 960 USD):
A19: • | B19: USD 2 880 = 2 380 (power head) + 400 (quick valve) + 100 (2 check valves) + 1 sada příslušenství k hlavě zdarma
A20: • | B20: USD 3 610 = 2 880 + 730 (reverzní kladivo, vnější průměr 220 mm) – zvoleno p. Kovářem
A21: • | B21: USD 3 860 = 3 610 + 250 (námořní LCL doprava do Prahy; expresní varianta byla 2 885 USD)
A22: • | B22: USD 3 960 = 3 860 + 100 (2 adaptéry á 50 USD, doobjednané) → částka na obchodní faktuře RCJX-2026041605A
