Workbook

Sheet Souhrn HS
A1: SOUHRN HS KÓDŮ – Hitachi Energy, faktura 129689
A3: Odesílatel (sender): | B3: Hitachi Energy UK Limited, Alpha Tower, Suffolk Street Queensway, Birmingham B1 1TT, GB (EORI GB641401089000)
A4: Příjemce (CZ receiver): | B4: Hitachi Energy Czech Republic s.r.o., Průmyslová 137, 541 01 Trutnov, CZ – EORI CZ08136289
A5: Faktura / projekt č.: | B5: 129689 ze dne 13.08.2026 (ref. HWUP PGGA; v e-mailu uvedeno „129869 -0-0-00-FRP“ – viz kontroly)
A6: Export declaration: | B6: 1400045712 ze dne 19.08.2026 (Hitachi Energy UK Ltd)
A7: MRN vývozu (SCP): | B7: 26GB000246SZVJOHJ0 (DSV Road, zásilka GBPFT608004151 / MSA850/012)
A8: Dodací podmínka (Incoterm): | B8: CPT Trutnov, Česká republika
A9: Země odeslání → určení: | B9: GB (Spojené království) → CZ (Česká republika)
A10: Měna: | B10: GBP
A11: Kusů / hmotnost: | B11: 2 palety; hrubá hmotnost 116 kg dle Packing Note (46 kg + 70 kg)
A12: Vykládka: | B12: 14./15.09.2026, Trutnov, Průmyslová 137
A14: Odesílatel | B14: HS kód (CN 8) | C14: TARIC (10) | D14: Popis zboží (CZ) | E14: Description (EN – zdrojové doklady) | F14: Čistá hmotnost (kg) | G14: Hrubá hmotnost (kg) | H14: Hrubá hm. – přepočet na 116 kg (ODHAD) | I14: Množství (ks) | J14: Celní hodnota (GBP) | K14: Země původu | L14: Incoterm | M14: CBAM | N14: Antidumping | O14: Poznámka / kontrola
A15: Hitachi Energy UK Limited | B15: 39269097 | C15: 3926909790 | D15: Ostatní výrobky z plastů – příslušenství kabeláže (zámky a záslepky portů RJ45 / USB) | E15: Cable Acc_RJ45 Port Lock Basic; Cable Acc_Port lock key; Cable Acc_USB Type-A Blue Port Blocker | F15: =SUMIF('Export decl – položky'!$B$4:$B$25,$C15,'Export decl – položky'!$E$4:$E$25) -> 2.09 | G15: =SUMIF('Export decl – položky'!$B$4:$B$25,$C15,'Export decl – položky'!$D$4:$D$25) -> 3.18 | H15: =ROUND(G15/SUM($G$15:$G$31)*116.0,2) -> 5.27 | I15: =SUMIF('Detail položek'!$F$4:$F$40,$C15,'Detail položek'!$G$4:$G$40) -> 14 | J15: =ROUND(SUMIF('Detail položek'!$F$4:$F$40,$C15,'Detail položek'!$I$4:$I$40),2) -> 664 | K15: KR – Jižní Korea | L15: CPT Trutnov, Česká republika | M15: Ne – nepodléhá (mimo přílohu I CBAM) | N15: Ne | O15: ⚠ Původ: faktura i Supplier Declaration uvádějí SOUTH KOREA (KR), export declaration uvádí „SK“ = Slovensko. Nutno opravit na KR.
A16: Hitachi Energy UK Limited | B16: 84433210 | C16: 8443321000 | D16: Laserová tiskárna připojitelná k zařízení pro automatizované zpracování dat | E16: IT HW_Printer Color LaserJet | F16: =SUMIF('Export decl – položky'!$B$4:$B$25,$C16,'Export decl – položky'!$E$4:$E$25) -> 2.09 | G16: =SUMIF('Export decl – položky'!$B$4:$B$25,$C16,'Export decl – položky'!$D$4:$D$25) -> 3.18 | H16: =ROUND(G16/SUM($G$15:$G$31)*116.0,2) -> 5.27 | I16: =SUMIF('Detail položek'!$F$4:$F$40,$C16,'Detail položek'!$G$4:$G$40) -> 1 | J16: =ROUND(SUMIF('Detail položek'!$F$4:$F$40,$C16,'Detail položek'!$I$4:$I$40),2) -> 406.45 | K16: CN – Čína | L16: CPT Trutnov, Česká republika | M16: Ne – nepodléhá (mimo přílohu I CBAM) | N16: Ne
A17: Hitachi Energy UK Limited | B17: 84715000 | C17: 8471500000 | D17: Zpracovatelské jednotky pro automatizované zpracování dat (průmyslový server) | E17: IT HW_Server CTOS: V2.0 | F17: =SUMIF('Export decl – položky'!$B$4:$B$25,$C17,'Export decl – položky'!$E$4:$E$25) -> 2.09 | G17: =SUMIF('Export decl – položky'!$B$4:$B$25,$C17,'Export decl – položky'!$D$4:$D$25) -> 3.18 | H17: =ROUND(G17/SUM($G$15:$G$31)*116.0,2) -> 5.27 | I17: =SUMIF('Detail položek'!$F$4:$F$40,$C17,'Detail položek'!$G$4:$G$40) -> 3 | J17: =ROUND(SUMIF('Detail položek'!$F$4:$F$40,$C17,'Detail položek'!$I$4:$I$40),2) -> 30215.35 | K17: CN – Čína | L17: CPT Trutnov, Česká republika | M17: Ne – nepodléhá (mimo přílohu I CBAM) | N17: Ne | O17: Nejvyšší hodnotová položka zásilky (30 215,35 GBP).
A18: Hitachi Energy UK Limited | B18: 84716060 | C18: 8471606000 | D18: Klávesnice k zařízení pro automatizované zpracování dat | E18: IT HW_K120 Wired USB Black Keyboard | F18: =SUMIF('Export decl – položky'!$B$4:$B$25,$C18,'Export decl – položky'!$E$4:$E$25) -> 2.09 | G18: =SUMIF('Export decl – položky'!$B$4:$B$25,$C18,'Export decl – položky'!$D$4:$D$25) -> 3.18 | H18: =ROUND(G18/SUM($G$15:$G$31)*116.0,2) -> 5.27 | I18: =SUMIF('Detail položek'!$F$4:$F$40,$C18,'Detail položek'!$G$4:$G$40) -> 1 | J18: =ROUND(SUMIF('Detail položek'!$F$4:$F$40,$C18,'Detail položek'!$I$4:$I$40),2) -> 13.33 | K18: CN – Čína | L18: CPT Trutnov, Česká republika | M18: Ne – nepodléhá (mimo přílohu I CBAM) | N18: Ne
A19: Hitachi Energy UK Limited | B19: 84716070 | C19: 8471607000 | D19: Ostatní vstupní jednotky – počítačová myš | E19: IT HW_Wired,USB Optical, Black, Mouse | F19: =SUMIF('Export decl – položky'!$B$4:$B$25,$C19,'Export decl – položky'!$E$4:$E$25) -> 2.09 | G19: =SUMIF('Export decl – položky'!$B$4:$B$25,$C19,'Export decl – položky'!$D$4:$D$25) -> 3.18 | H19: =ROUND(G19/SUM($G$15:$G$31)*116.0,2) -> 5.27 | I19: =SUMIF('Detail položek'!$F$4:$F$40,$C19,'Detail položek'!$G$4:$G$40) -> 1 | J19: =ROUND(SUMIF('Detail položek'!$F$4:$F$40,$C19,'Detail položek'!$I$4:$I$40),2) -> 8.33 | K19: CN – Čína | L19: CPT Trutnov, Česká republika | M19: Ne – nepodléhá (mimo přílohu I CBAM) | N19: Ne
A20: Hitachi Energy UK Limited | B20: 84718000 | C20: 8471800000 | D20: Ostatní jednotky zařízení pro automatizované zpracování dat (KVM přepínač USB/DVI) | E20: Switch 2port USB DVI Dual link | F20: =SUMIF('Export decl – položky'!$B$4:$B$25,$C20,'Export decl – položky'!$E$4:$E$25) -> 2.09 | G20: =SUMIF('Export decl – položky'!$B$4:$B$25,$C20,'Export decl – položky'!$D$4:$D$25) -> 3.18 | H20: =ROUND(G20/SUM($G$15:$G$31)*116.0,2) -> 5.27 | I20: =SUMIF('Detail položek'!$F$4:$F$40,$C20,'Detail položek'!$G$4:$G$40) -> 2 | J20: =ROUND(SUMIF('Detail položek'!$F$4:$F$40,$C20,'Detail položek'!$I$4:$I$40),2) -> 756 | K20: TW – Tchaj-wan | L20: CPT Trutnov, Česká republika | M20: Ne – nepodléhá (mimo přílohu I CBAM) | N20: Ne | O20: Na faktuře 2× samostatný řádek (ř. 5 a ř. 37), sloučeno.
A21: Hitachi Energy UK Limited | B21: 85044087 | C21: 8504408790 | D21: Statický měnič – modulární invertor a jeho příslušenství (ochranný kryt) | E21: Inverter_Modular Bravo 25-110/230-277; Cab Acc_Back protection shell for BRAVO | F21: =SUMIF('Export decl – položky'!$B$4:$B$25,$C21,'Export decl – položky'!$E$4:$E$25) -> 2.09 | G21: =SUMIF('Export decl – položky'!$B$4:$B$25,$C21,'Export decl – položky'!$D$4:$D$25) -> 3.18 | H21: =ROUND(G21/SUM($G$15:$G$31)*116.0,2) -> 5.27 | I21: =SUMIF('Detail položek'!$F$4:$F$40,$C21,'Detail položek'!$G$4:$G$40) -> 2 | J21: =ROUND(SUMIF('Detail položek'!$F$4:$F$40,$C21,'Detail položek'!$I$4:$I$40),2) -> 2914 | K21: BE – Belgie | L21: CPT Trutnov, Česká republika | M21: Ne – nepodléhá (mimo přílohu I CBAM) | N21: Ne | O21: ⚠ Rozpor HS: faktura + Supplier Declaration uvádějí 8504 40 86, export declaration 8504 40 87 90. Nutno ověřit správné podpoložky v TARIC.
A22: Hitachi Energy UK Limited | B22: 85176200 | C22: 8517620000 | D22: Přístroje pro příjem, konverzi, vysílání nebo regeneraci hlasu, obrazu nebo jiných dat (SFP moduly, optické převodníky, KVM over IP, ethernetový přepínač) | E22: SFP_Hardened; NPort; TCF-90; Router DVI-I KVM IP Rec./Transm.; SFP_SM; SFP Transceivers; Switch Ether_SEL 2741 SDN | F22: =SUMIF('Export decl – položky'!$B$4:$B$25,$C22,'Export decl – položky'!$E$4:$E$25) -> 6.27 | G22: =SUMIF('Export decl – položky'!$B$4:$B$25,$C22,'Export decl – položky'!$D$4:$D$25) -> 9.54 | H22: =ROUND(G22/SUM($G$15:$G$31)*116.0,2) -> 15.81 | I22: =SUMIF('Detail položek'!$F$4:$F$40,$C22,'Detail položek'!$G$4:$G$40) -> 37 | J22: =ROUND(SUMIF('Detail položek'!$F$4:$F$40,$C22,'Detail položek'!$I$4:$I$40),2) -> 12677.33 | K22: TW – Tchaj-wan; CN – Čína; US – USA | L22: CPT Trutnov, Česká republika | M22: Ne – nepodléhá (mimo přílohu I CBAM) | N22: Ne | O22: ⚠ Rozpor HS: SFP-GMM-2K je na faktuře pod 8517 60 00, export declaration ho zařadila do 8517 62 00. ⚠ Jeden HS kód, tři země původu (TW 8 215,60 / CN 849,90 / US 3 611,83 GBP) – pro JSD nutno rozdělit na 3 položky, viz list „Původ – rozpad“.
A23: Hitachi Energy UK Limited | B23: 85235110 | C23: 8523511000 | D23: Polovodičové energeticky nezávislé paměťové zařízení – externí SSD disk (nezaznamenané) | E23: TB External SSD Hard Drive | F23: =SUMIF('Export decl – položky'!$B$4:$B$25,$C23,'Export decl – položky'!$E$4:$E$25) -> 2.09 | G23: =SUMIF('Export decl – položky'!$B$4:$B$25,$C23,'Export decl – položky'!$D$4:$D$25) -> 3.18 | H23: =ROUND(G23/SUM($G$15:$G$31)*116.0,2) -> 5.27 | I23: =SUMIF('Detail položek'!$F$4:$F$40,$C23,'Detail položek'!$G$4:$G$40) -> 1 | J23: =ROUND(SUMIF('Detail položek'!$F$4:$F$40,$C23,'Detail položek'!$I$4:$I$40),2) -> 630 | K23: CN – Čína | L23: CPT Trutnov, Česká republika | M23: Ne – nepodléhá (mimo přílohu I CBAM) | N23: Ne
A24: Hitachi Energy UK Limited | B24: 85285210 | C24: 8528521000 | D24: Monitor schopný přímého připojení k zařízení pro automatizované zpracování dat | E24: E27 G5 - E-Series - LED monitor | F24: =SUMIF('Export decl – položky'!$B$4:$B$25,$C24,'Export decl – položky'!$E$4:$E$25) -> 2.09 | G24: =SUMIF('Export decl – položky'!$B$4:$B$25,$C24,'Export decl – položky'!$D$4:$D$25) -> 3.18 | H24: =ROUND(G24/SUM($G$15:$G$31)*116.0,2) -> 5.27 | I24: =SUMIF('Detail položek'!$F$4:$F$40,$C24,'Detail položek'!$G$4:$G$40) -> 2 | J24: =ROUND(SUMIF('Detail položek'!$F$4:$F$40,$C24,'Detail položek'!$I$4:$I$40),2) -> 255.3 | K24: CN – Čína | L24: CPT Trutnov, Česká republika | M24: Ne – nepodléhá (mimo přílohu I CBAM) | N24: Ne
A25: Hitachi Energy UK Limited | B25: 85363010 | C25: 8536301000 | D25: Přístroje k ochraně elektrických obvodů pro napětí ≤ 1 000 V – přepěťová ochrana | E25: Surge proctective LV MBG S-PRO | F25: =SUMIF('Export decl – položky'!$B$4:$B$25,$C25,'Export decl – položky'!$E$4:$E$25) -> 2.09 | G25: =SUMIF('Export decl – položky'!$B$4:$B$25,$C25,'Export decl – položky'!$D$4:$D$25) -> 3.18 | H25: =ROUND(G25/SUM($G$15:$G$31)*116.0,2) -> 5.27 | I25: =SUMIF('Detail položek'!$F$4:$F$40,$C25,'Detail položek'!$G$4:$G$40) -> 1 | J25: =ROUND(SUMIF('Detail položek'!$F$4:$F$40,$C25,'Detail položek'!$I$4:$I$40),2) -> 164 | K25: DE – Německo | L25: CPT Trutnov, Česká republika | M25: Ne – nepodléhá (mimo přílohu I CBAM) | N25: Ne
A26: Hitachi Energy UK Limited | B26: 85366990 | C26: 8536699099 | D26: Zástrčky a zásuvky, ostatní – adaptér D-SUB 9pin | E26: Adapter_D SUB Female 9 pole | F26: =SUMIF('Export decl – položky'!$B$4:$B$25,$C26,'Export decl – položky'!$E$4:$E$25) -> 2.09 | G26: =SUMIF('Export decl – položky'!$B$4:$B$25,$C26,'Export decl – položky'!$D$4:$D$25) -> 3.18 | H26: =ROUND(G26/SUM($G$15:$G$31)*116.0,2) -> 5.27 | I26: =SUMIF('Detail položek'!$F$4:$F$40,$C26,'Detail položek'!$G$4:$G$40) -> 4 | J26: =ROUND(SUMIF('Detail položek'!$F$4:$F$40,$C26,'Detail položek'!$I$4:$I$40),2) -> 59.68 | K26: LI – Lichtenštejnsko | L26: CPT Trutnov, Česká republika | M26: Ne – nepodléhá (mimo přílohu I CBAM) | N26: Ne
A27: Hitachi Energy UK Limited | B27: 85367000 | C27: 8536700099 | D27: Konektory pro optická vlákna, svazky optických vláken nebo optické kabely | E27: Converter_Module DIN rail MDR,04 x ST-PC | F27: =SUMIF('Export decl – položky'!$B$4:$B$25,$C27,'Export decl – položky'!$E$4:$E$25) -> 2.11 | G27: =SUMIF('Export decl – položky'!$B$4:$B$25,$C27,'Export decl – položky'!$D$4:$D$25) -> 3.22 | H27: =ROUND(G27/SUM($G$15:$G$31)*116.0,2) -> 5.34 | I27: =SUMIF('Detail položek'!$F$4:$F$40,$C27,'Detail položek'!$G$4:$G$40) -> 4 | J27: =ROUND(SUMIF('Detail položek'!$F$4:$F$40,$C27,'Detail položek'!$I$4:$I$40),2) -> 189.73 | K27: TN – Tunisko | L27: CPT Trutnov, Česká republika | M27: Ne – nepodléhá (mimo přílohu I CBAM) | N27: Ne | O27: Na faktuře uvedeno jako „8536700“ (7 míst) – správně 8536 70 00.
A28: Hitachi Energy UK Limited | B28: 85437090 | C28: 8543709099 | D28: Elektrické stroje a přístroje s vlastní individuální funkcí, ostatní – USB extender, GPS časový server | E28: Cable_1 USB 2.0 Cat5 Extender,60m; GPS LANTIME M3000-IMS | F28: =SUMIF('Export decl – položky'!$B$4:$B$25,$C28,'Export decl – položky'!$E$4:$E$25) -> 4.18 | G28: =SUMIF('Export decl – položky'!$B$4:$B$25,$C28,'Export decl – položky'!$D$4:$D$25) -> 6.36 | H28: =ROUND(G28/SUM($G$15:$G$31)*116.0,2) -> 10.54 | I28: =SUMIF('Detail položek'!$F$4:$F$40,$C28,'Detail položek'!$G$4:$G$40) -> 2 | J28: =ROUND(SUMIF('Detail položek'!$F$4:$F$40,$C28,'Detail položek'!$I$4:$I$40),2) -> 6396.5 | K28: TW – Tchaj-wan; DE – Německo | L28: CPT Trutnov, Česká republika | M28: Ne – nepodléhá (mimo přílohu I CBAM) | N28: Ne | O28: ⚠ Jeden HS kód, dvě země původu (TW 98,00 / DE 6 298,50 GBP) – pro JSD rozdělit, viz list „Původ – rozpad“.
A29: Hitachi Energy UK Limited | B29: 85444210 | C29: 8544421000 | D29: Elektrické vodiče pro napětí ≤ 1 000 V, opatřené přípojkami, pro telekomunikace (patch kabel Cat6) | E29: Cable_Cat6, RJ45-Male RJ45 Male S/FTP | F29: =SUMIF('Export decl – položky'!$B$4:$B$25,$C29,'Export decl – položky'!$E$4:$E$25) -> 2.09 | G29: =SUMIF('Export decl – položky'!$B$4:$B$25,$C29,'Export decl – položky'!$D$4:$D$25) -> 3.18 | H29: =ROUND(G29/SUM($G$15:$G$31)*116.0,2) -> 5.27 | I29: =SUMIF('Detail položek'!$F$4:$F$40,$C29,'Detail položek'!$G$4:$G$40) -> 5 | J29: =ROUND(SUMIF('Detail položek'!$F$4:$F$40,$C29,'Detail položek'!$I$4:$I$40),2) -> 25 | K29: CN – Čína | L29: CPT Trutnov, Česká republika | M29: Ne – nepodléhá (mimo přílohu I CBAM) | N29: Ne
A30: Hitachi Energy UK Limited | B30: 85444290 | C30: 8544429090 | D30: Ostatní elektrické vodiče pro napětí ≤ 1 000 V, opatřené přípojkami (DVI, HDMI, USB, D-Sub kabely) | E30: Cable Comms DVI-D KVM; Cable comms D-sub; Cable_Port DVI-D; Cable Comm USB 2.0; Cable Comm HDMI-DVI | F30: =SUMIF('Export decl – položky'!$B$4:$B$25,$C30,'Export decl – položky'!$E$4:$E$25) -> 6.27 | G30: =SUMIF('Export decl – položky'!$B$4:$B$25,$C30,'Export decl – položky'!$D$4:$D$25) -> 9.54 | H30: =ROUND(G30/SUM($G$15:$G$31)*116.0,2) -> 15.81 | I30: =SUMIF('Detail položek'!$F$4:$F$40,$C30,'Detail položek'!$G$4:$G$40) -> 12 | J30: =ROUND(SUMIF('Detail položek'!$F$4:$F$40,$C30,'Detail položek'!$I$4:$I$40),2) -> 387.07 | K30: CN – Čína; TW – Tchaj-wan; VN – Vietnam | L30: CPT Trutnov, Česká republika | M30: Ne – nepodléhá (mimo přílohu I CBAM) | N30: Ne | O30: ⚠ Jeden HS kód, tři země původu (CN 297,28 / TW 50,00 / VN 39,79 GBP) – pro JSD rozdělit, viz list „Původ – rozpad“.
A31: Hitachi Energy UK Limited | B31: 85447000 | C31: 8544700099 | D31: Kabely z optických vláken | E31: Fiber Acc_MDRII_OM1_LC_SplicePatch | F31: =SUMIF('Export decl – položky'!$B$4:$B$25,$C31,'Export decl – položky'!$E$4:$E$25) -> 2.09 | G31: =SUMIF('Export decl – položky'!$B$4:$B$25,$C31,'Export decl – položky'!$D$4:$D$25) -> 3.18 | H31: =ROUND(G31/SUM($G$15:$G$31)*116.0,2) -> 5.27 | I31: =SUMIF('Detail položek'!$F$4:$F$40,$C31,'Detail položek'!$G$4:$G$40) -> 6 | J31: =ROUND(SUMIF('Detail položek'!$F$4:$F$40,$C31,'Detail položek'!$I$4:$I$40),2) -> 1199.94 | K31: GB – Spojené království | L31: CPT Trutnov, Česká republika | M31: Ne – nepodléhá (mimo přílohu I CBAM) | N31: ⚠ Ověřit v TARIC | O31: ⚠ ANTIDUMPING: EU vede antidumpingová a vyrovnávací opatření na kabely z optických vláken původu ČLNA a Indie. Zde deklarován původ GB → opatření by se uplatnit neměla, ale původ musí být doložen. Ověřit v TARIC ke dni propuštění. Jediná položka zásilky s původem GB.
A32: CELKEM | F32: =SUM(F15:F31) -> 46 | G32: =SUM(G15:G31) -> 70 | H32: =SUM(H15:H31) -> 116.01 | I32: =SUM(I15:I31) -> 98 | J32: =SUM(J15:J31) -> 56962.01 | O32: Kontrola: hodnota musí = 56 962,01 GBP; množství = 98 ks
A34: KONTROLA HMOTNOSTI
A35: Hrubá hmotnost dle Packing Note (2 palety: 46 + 70 kg) | G35: 116
A36: Hrubá hmotnost dle Export Declaration (pole 30) | G36: 70
A37: ROZDÍL (nedoloženo) | G37: =G35-G36 -> 46
A39: POZOR – hmotnosti: zdrojové doklady NEOBSAHUJÍ hmotnosti na položku. Export Declaration rozpočítala 70,000 kg rovnoměrně na 22 položek (3,180 kg na položku) a jako „net“ použila 46,000 kg – což je ve skutečnosti hrubá hmotnost palety č. 1 z Packing Note. Hodnoty ve sloupcích „Čistá hmotnost“ a „Hrubá hmotnost“ jsou tedy systémové výplně, nikoli skutečné hmotnosti. Sloupec H je pomocný přepočet skutečných 116 kg – rovněž ODHAD. Před podáním JSD si vyžádejte skutečné hmotnosti na položku.

Sheet Export decl – položky
A1: Export Declaration Instruction Sheet č. 1400045712 – položky (zdroj hmotností)
A3: Pol. č. | B3: TARIC (10) | C3: Množství (ks) | D3: Hrubá hm. (kg) | E3: Čistá hm. (kg) | F3: Země původu | G3: Hodnota (GBP) | H3: Popis (EN)
A4: 1 | B4: 8536700099 | C4: 4 | D4: 3.22 | E4: 2.11 | F4: TN | G4: 189.73 | H4: Converter_Module DIN rail MDR,04 x ST-PC
A5: 2 | B5: 3926909790 | C5: 14 | D5: 3.18 | E5: 2.09 | F5: SK | G5: 664 | H5: Cable Acc
A6: 3 | B6: 8443321000 | C6: 1 | D6: 3.18 | E6: 2.09 | F6: CN | G6: 406.45 | H6: IT HW_Printer Color LaserJet
A7: 4 | B7: 8471500000 | C7: 3 | D7: 3.18 | E7: 2.09 | F7: CN | G7: 30215.35 | H7: IT HW_Server CTOS: V2.0
A8: 5 | B8: 8471606000 | C8: 1 | D8: 3.18 | E8: 2.09 | F8: CN | G8: 13.33 | H8: IT HW_K120 Wired USB Black Keyboard
A9: 6 | B9: 8471607000 | C9: 1 | D9: 3.18 | E9: 2.09 | F9: CN | G9: 8.33 | H9: IT HW_Wired,USB Optical, Black, Mouse
A10: 7 | B10: 8471800000 | C10: 2 | D10: 3.18 | E10: 2.09 | F10: TW | G10: 756 | H10: Switch 2port USB DVI Dual link
A11: 8 | B11: 8504408790 | C11: 2 | D11: 3.18 | E11: 2.09 | F11: BE | G11: 2914 | H11: Inverter_Modular Bravo; Back protection shell
A12: 9 | B12: 8517620000 | C12: 26 | D12: 3.18 | E12: 2.09 | F12: TW | G12: 8215.6 | H12: SFP_Hardened; Router DVI-I KVM IP Rec./Transm.; NPort; TCF-90; SFP_SM
A13: 10 | B13: 8517620000 | C13: 10 | D13: 3.18 | E13: 2.09 | F13: CN | G13: 849.9 | H13: SFP Transceivers
A14: 11 | B14: 8517620000 | C14: 1 | D14: 3.18 | E14: 2.09 | F14: US | G14: 3611.83 | H14: Switch Ether_SEL 2741 SDN
A15: 12 | B15: 8523511000 | C15: 1 | D15: 3.18 | E15: 2.09 | F15: CN | G15: 630 | H15: TB External SSD Hard Drive
... A25: 22 | B25: 8544700099 | C25: 6 | D25: 3.18 | E25: 2.09 | F25: GB | G25: 1199.94 | H25: Fiber Acc_MDRII_OM1_LC_SplicePatch
A26: CELKEM | C26: =SUM(C4:C25) -> 98 | D26: =SUM(D4:D25) -> 70 | E26: =SUM(E4:E25) -> 46 | G26: =SUM(G4:G25) -> 56962.01
A28: Hmotnosti v tomto listu jsou systémově rozpočítané (3,180 kg hrubá / 2,090 kg čistá na položku u 21 z 22 položek). Součet hrubé = 70,000 kg a čisté = 46,000 kg odpovídá přesně hmotnostem obou palet z Packing Note (70 kg a 46 kg). Nejde tedy o skutečné čisté hmotnosti – viz kontroly.

Sheet Detail položek
A1: Rozpis položek faktury 129689 a jejich zařazení pod HS kódy
A3: Ř. faktury | B3: Description (EN) | C3: Part No | D3: HS dle faktury | E3: Pol. export decl. | F3: TARIC dle export decl. | G3: Množství (ks) | H3: Země původu (faktura / Supplier Decl.) | I3: Hodnota (GBP) | J3: Poznámka
A4: 1 | B4: IT HW_Server CTOS: V2.0 | C4: ECU-479-V1-S1 | D4: 84715000 | E4: 4 | F4: 8471500000 | G4: 2 | H4: CHINA | I4: 18299.18
A5: 2 | B5: SFP_Hardened 1250-ED, MM1310/LC 2km | C5: SFP-GMM-2K | D5: 85176000 | E5: 9 | F5: 8517620000 | G5: 12 | H5: TAIWAN | I5: 420 | J5: ⚠ Přeřazeno: faktura 8517 60 00 → export decl. 8517 62 00
A6: 3 | B6: IT HW_Server CTOS: V2.0 | C6: ECU-479-V1-S1 | D6: 84715000 | E6: 4 | F6: 8471500000 | G6: 1 | H6: CHINA | I6: 11916.17
A7: 4 | B7: Cable_1 USB 2.0 Cat5 Extender,60m | C7: UCE260 | D7: 85437090 | E7: 16 | F7: 8543709099 | G7: 1 | H7: TAIWAN | I7: 98
A8: 5 | B8: Switch 2port USB DVI Dual link | C8: CS1642A | D8: 84718000 | E8: 7 | F8: 8471800000 | G8: 1 | H8: TAIWAN | I8: 378
A9: 6 | B9: IT HW_RS-232/422/485 4port rugged device | C9: NPort S9450I-2M-ST-HV-T | D9: 85176200 | E9: 9 | F9: 8517620000 | G9: 2 | H9: TAIWAN | I9: 3308
A10: 7 | B10: IT Net RS-232 MM ST FO Converter | C10: TCF-90-M-ST | D10: 85176200 | E10: 9 | F10: 8517620000 | G10: 8 | H10: TAIWAN | I10: 1216
A11: 8 | B11: Cable Comms 1.8M DVI-D Single-Link KVM | C11: 2L-7D02V | D11: 85444290 | E11: 20 | F11: 8544429090 | G11: 2 | H11: TAIWAN | I11: 50
A12: 9 | B12: Cable Acc_RJ45 Port Lock Basic | C12: NL03P1 | D12: 39269097 | E12: 2 | F12: 3926909790 | G12: 8 | H12: SOUTH KOREA | I12: 280 | J12: ⚠ Export decl. uvádí „SK“ (Slovensko) místo KR (Jižní Korea)
A13: 10 | B13: Cable Acc_Port lock key | C13: U03DB | D13: 39269097 | E13: 2 | F13: 3926909790 | G13: 2 | H13: SOUTH KOREA | I13: 128 | J13: ⚠ Export decl. uvádí „SK“ (Slovensko) místo KR (Jižní Korea)
A14: 11 | B14: IT HW_K120 Wired USB Black Keyboard | C14: 920-002524 | D14: 84716060 | E14: 5 | F14: 8471606000 | G14: 1 | H14: CHINA | I14: 13.33
A15: 12 | B15: IT HW_Wired,USB Optical, Black, Mouse | C15: 910-001793 | D15: 84716070 | E15: 6 | F15: 8471607000 | G15: 1 | H15: CHINA | I15: 8.33
A16: 13 | B16: Cable Acc_USB Type-A Blue Port Blocker | C16: UL03P1DB | D16: 39269097 | E16: 2 | F16: 3926909790 | G16: 4 | H16: SOUTH KOREA | I16: 256 | J16: ⚠ Export decl. uvádí „SK“ (Slovensko) místo KR (Jižní Korea)
A17: 14 | B17: IT HW_Printer Color LaserJet | C17: M455dn | D17: 84433210 | E17: 3 | F17: 8443321000 | G17: 1 | H17: CHINA | I17: 406.45
A18: 15 | B18: Router DVI-I 2 Displ KVM IP Receiver | C18: KE6940AR | D18: 85176200 | E18: 9 | F18: 8517620000 | G18: 1 | H18: TAIWAN | I18: 1567
A19: 16 | B19: Router DVI-I 2 Displ KVM IP Transmitt | C19: KE6940AT | D19: 85176200 | E19: 9 | F19: 8517620000 | G19: 1 | H19: TAIWAN | I19: 1567
A20: 17 | B20: TB External SSD Hard Drive | C20: 1 x diskAshur2 - 2 TB (SSD) | D20: 85235110 | E20: 12 | F20: 8523511000 | G20: 1 | H20: CHINA | I20: 630
A21: 18 | B21: Adapter_D SUB Female 9 pole | C21: NADB9FF | D21: 85366990 | E21: 15 | F21: 8536699099 | G21: 4 | H21: LIECHTENSTEIN | I21: 59.68
A22: 19 | B22: E27 G5 - E-Series - LED monitor | C22: HP E27 G5 FHD Monitor | D22: 85285210 | E22: 13 | F22: 8528521000 | G22: 2 | H22: CHINA | I22: 255.3
A23: 20 | B23: Inverter_Modular Bravo 25-110/230-277 | C23: S62AD5E0104SN000F001 | D23: 85044086 | E23: 8 | F23: 8504408790 | G23: 1 | H23: BELGIUM | I23: 1314 | J23: ⚠ Rozpor: faktura 8504 40 86 → export decl. 8504 40 87 90
A24: 21 | B24: Cab Acc_Back protection shell for BRAVO | C24: T329005049 | D24: 85044086 | E24: 8 | F24: 8504408790 | G24: 1 | H24: BELGIUM | I24: 1600 | J24: ⚠ Rozpor: faktura 8504 40 86 → export decl. 8504 40 87 90
A25: 22 | B25: Converter_Module DIN rail MDR,04 x ST-PC | C25: 85026629 | D25: 8536700 | E25: 1 | F25: 8536700099 | G25: 4 | H25: TUNESIEN (TN) | I25: 189.73 | J25: Na faktuře 7místný kód „8536700“ → správně 8536 70 00
A26: 23 | B26: Fiber Acc_MDRII_OM1_LC_SplicePatch | C26: 85153715 | D26: 85447000 | E26: 22 | F26: 8544700099 | G26: 6 | H26: UNITED KINGDOM | I26: 1199.94
A27: 24 | B27: SFP_1000BASE-T, SFP-GB-GE-T,Copper | C27: 262416 | D27: 85176200 | E27: 10 | F27: 8517620000 | G27: 1 | H27: CHINA | I27: 86.4
A28: 25 | B28: SFP_SM, 1000 BASE-LX, 1310NM | C28: 261976 | D28: 85176200 | E28: 9 | F28: 8517620000 | G28: 2 | H28: TAIWAN | I28: 137.6
A29: 26 | B29: GPS LANTIME M3000-IMS | C29: 30015364 | D29: 85437090 | E29: 17 | F29: 8543709099 | G29: 1 | H29: GERMANY | I29: 6298.5
A30: 27 | B30: Surge proctective LV MBG S-PRO | C30: 00026790 | D30: 85363010 | E30: 14 | F30: 8536301000 | G30: 1 | H30: GERMANY | I30: 164
A31: 28 | B31: SFP Transceiver 1000BASE-LX | C31: 00262416 | D31: 85176200 | E31: 10 | F31: 8517620000 | G31: 1 | H31: CHINA | I31: 163.5
A32: 29 | B32: SFP Transceiver 100BASE-FX Multi mode | C32: 00261976 | D32: 85176200 | E32: 10 | F32: 8517620000 | G32: 8 | H32: CHINA | I32: 600
A33: 30 | B33: Switch Ether_SEL 2741 SDN | C33: 2741#JJ2N | D33: 85176200 | E33: 11 | F33: 8517620000 | G33: 1 | H33: USA | I33: 3611.83
A34: 31 | B34: Cable comms Female 9 Pin D-sub F/M,2M | C34: 226-2762 | D34: 85444290 | E34: 19 | F34: 8544429090 | G34: 4 | H34: CHINA | I34: 234.84
A35: 32 | B35: Cable_Port to Male DVI-D Dual Link -2M | C35: 251-3280 | D35: 85444290 | E35: 19 | F35: 8544429090 | G35: 1 | H35: CHINA | I35: 39.12
A36: 33 | B36: Cable_Cat6, RJ45-Male RJ45 Male S/FTP | C36: 411-245 | D36: 85444210 | E36: 18 | F36: 8544421000 | G36: 5 | H36: CHINA | I36: 25
A37: 34 | B37: Cable Comm USB 2.0, Male A to B, 2m | C37: 252-7138 | D37: 85444290 | E37: 21 | F37: 8544429090 | G37: 1 | H37: VIETNAM | I37: 39.79
... A40: 37 | B40: Switch 2port USB DVI Dual link | C40: CS1642A | D40: 84718000 | E40: 7 | F40: 8471800000 | G40: 1 | H40: TAIWAN | I40: 378
A41: CELKEM | G41: =SUM(G4:G40) -> 98 | I41: =SUM(I4:I40) -> 56962.01 | J41: Musí souhlasit s fakturou: 56 962,01 GBP / 98 ks

Sheet Původ – rozpad
A1: Rozpad HS kódů podle země původu (pro rozdělení položek v JSD)
A2: Souhrn na listu „Souhrn HS“ slučuje řádky na unikátní HS kódy v rámci odesílatele podle standardního pravidla. Tři HS kódy ale zahrnují více zemí původu – pro celní prohlášení je nutné je rozdělit takto:
A6: HS kód (CN 8) | B6: TARIC (10) | C6: Země původu | D6: Množství (ks) | E6: Hodnota (GBP) | F6: Pol. export decl.
A7: 85367000 | B7: 8536700099 | C7: TN – Tunisko | D7: 4 | E7: 189.73 | F7: 1
A8: 39269097 | B8: 3926909790 | C8: KR – Jižní Korea (export decl. chybně „SK“) | D8: 14 | E8: 664 | F8: 2
A9: 84433210 | B9: 8443321000 | C9: CN – Čína | D9: 1 | E9: 406.45 | F9: 3
A10: 84715000 | B10: 8471500000 | C10: CN – Čína | D10: 3 | E10: 30215.35 | F10: 4
A11: 84716060 | B11: 8471606000 | C11: CN – Čína | D11: 1 | E11: 13.33 | F11: 5
A12: 84716070 | B12: 8471607000 | C12: CN – Čína | D12: 1 | E12: 8.33 | F12: 6
A13: 84718000 | B13: 8471800000 | C13: TW – Tchaj-wan | D13: 2 | E13: 756 | F13: 7
A14: 85044087 | B14: 8504408790 | C14: BE – Belgie | D14: 2 | E14: 2914 | F14: 8
A15: 85176200 | B15: 8517620000 | C15: TW – Tchaj-wan | D15: 26 | E15: 8215.6 | F15: 9
A16: 85176200 | B16: 8517620000 | C16: CN – Čína | D16: 10 | E16: 849.9 | F16: 10
A17: 85176200 | B17: 8517620000 | C17: US – USA | D17: 1 | E17: 3611.83 | F17: 11
A18: 85235110 | B18: 8523511000 | C18: CN – Čína | D18: 1 | E18: 630 | F18: 12
... A28: 85447000 | B28: 8544700099 | C28: GB – Spojené království | D28: 6 | E28: 1199.94 | F28: 22
A29: CELKEM | D29: =SUM(D7:D28) -> 98 | E29: =SUM(E7:E28) -> 56962.01
A31: Žlutě zvýrazněné řádky = HS kódy, které se na listu „Souhrn HS“ objevují na jednom řádku, ale mají různý původ.

Sheet Kontroly a upozornění
A1: KONTROLY A UPOZORNĚNÍ – Hitachi Energy, faktura 129689 (dovoz GB → CZ)
A3: 1) PREFERENČNÍ VĚTA (COO) – NENÍ V DOKLADECH | B3: KRITICKÉ
A4: ❌ V žádném z doložených dokladů (Customs Invoice 129689, Packing Note, Export Declaration Instruction Sheet 1400045712, Supplier's Declaration concerning Export Control) NENÍ uvedena preferenční věta / prohlášení o původu.
A5: Důsledek: NELZE uplatnit preferenční sazební zacházení podle Dohody o obchodu a spolupráci EU–UK (TCA). Zboží bude propuštěno se standardní celní sazbou erga omnes.
A6: Pozn.: Jediná položka, která by na preferenci podle TCA vůbec mohla dosáhnout, je Fiber Acc_MDRII_OM1_LC_SplicePatch (TARIC 8544 70 00 99, původ UNITED KINGDOM, hodnota 1 199,94 GBP). Bez prohlášení o původu na faktuře ji uplatnit nelze.
A7: Ostatní zboží má původ CN / TW / KR / US / VN / TN / LI / DE / BE – na preferenci podle TCA nárok nemá bez ohledu na prohlášení.
A8: ➤ DOPORUČENÍ: vyžádat od Hitachi Energy UK Ltd fakturu s prohlášením o původu, pokud na preferenci u položky 8544 70 00 99 chtějí nárokovat. Jinak clít standardní sazbou.
A10: 2) REX / REFERENČNÍ ČÍSLO VÝVOZCE – NENÍ NA FAKTUŘE | B10: KRITICKÉ
A11: ❌ Na faktuře 129689 NENÍ uvedeno žádné číslo REX ani jiné referenční číslo vývozce pro účely prohlášení o původu.
A12: Na faktuře je uvedeno pouze EORI vývozce: GB641401089000 (a VAT GB 641 4010 89, Reg. in England No. 2985756). Samotné EORI ale prohlášením o původu není.
A13: Pozn. k systematice: pro směr UK → EU se v režimu TCA neuvádí REX, ale referenční číslo vývozce, kterým je jeho britské EORI, a to VŽDY spolu s textem prohlášení o původu. REX se používá u GSP a některých jiných dohod. Zde chybí samotný text prohlášení, takže původ nelze prokázat ani jednou z cest.
A14: ➤ ZÁVĚR: REX není přítomen; prohlášení o původu není přítomno. Preferenci neuplatňovat.
A16: 3) CBAM – ZÁSILKA NEPODLÉHÁ | B16: OK
A17: Žádný z 17 HS kódů této zásilky (kap. 39, 84, 85) není uveden v příloze I nařízení o CBAM (cement, elektřina, hnojiva, železo a ocel, hliník, vodík). Zásilka tedy CBAM nepodléhá a deklaraci Y-kódu nevyžaduje.
A18: Pro úplnost byl příjemce přesto dohledán v registru reference/CBAM_receivers_CZ.xlsx (list List1, řádek 16):
A19: Firma: Hitachi Energy Czech Republic s.r.o.
A20: EORI: CZ08136289
A21: Y KÓD: Y128 (povolení uděleno – plně autorizovaný deklarant CBAM)
A22: Povolení: CBAM-CZ-2025-AQH22019015074
A23: Podaná žádost: – (neuvedeno) | Datum vydání: neuvedeno
A24: ➤ Příjemce je v registru veden a má platné povolení Y128. Pro tuto zásilku se však nepoužije.
A26: 4) ANTIDUMPING | B26: OVĚŘIT
A27: ⚠ TARIC 8544 70 00 99 – Kabely z optických vláken (Fiber Acc_MDRII_OM1_LC_SplicePatch, 6 ks, 1 199,94 GBP): EU vede na kabely z optických vláken antidumpingová a vyrovnávací (antisubvenční) opatření vůči původu ČLR a Indie.
A28: V této zásilce je deklarován původ UNITED KINGDOM (GB), opatření by se tedy uplatnit neměla – původ je však nutné doložit. Ověřte v TARIC ke dni propuštění do volného oběhu.
A29: U ostatních 16 HS kódů zásilky nejsou známa žádná antidumpingová opatření relevantní pro deklarované země původu.
A31: 5) ROZPORY MEZI DOKLADY – NUTNO VYJASNIT S ODESÍLATELEM | B31: K VYJASNĚNÍ
A32: ⚠ ZEMĚ PŮVODU (3926 90 97 90): Faktura i Supplier's Declaration uvádějí u položek NL03P1, U03DB a UL03P1DB (14 ks, 664,00 GBP) původ SOUTH KOREA. Export Declaration u téže položky uvádí kód „SK“, což je Slovensko. Správný kód pro Jižní Koreu je KR. Před podáním JSD opravit – rozdíl EU vs. třetí země zásadně mění clo.
A33: ⚠ HS KÓD (SFP-GMM-2K, 12 ks, 420,00 GBP): faktura uvádí 8517 60 00, Export Declaration 8517 62 00. Do souhrnu použit kód z Export Declaration (8517 62 00). Potvrdit s odesílatelem.
A34: ⚠ HS KÓD (Inverter Bravo + kryt, 2 ks, 2 914,00 GBP): faktura a Supplier's Declaration uvádějí 8504 40 86, Export Declaration 8504 40 87 90. Podpoložku ověřit v TARIC a sjednotit.
A35: ⚠ HS KÓD (Converter_Module DIN rail MDR): na faktuře uveden jako sedmimístný „8536700“ – správně 8536 70 00.
A36: ⚠ HMOTNOSTI: Export Declaration rozpočítala 70,000 kg rovnoměrně na 22 položek (3,180 kg / položku) a jako čistou hmotnost uvádí celkem 46,000 kg. To přesně odpovídá hrubým hmotnostem obou palet z Packing Note (70 kg a 46 kg). Skutečná hrubá hmotnost zásilky je 116 kg (46 + 70). Hmotnosti na položku tedy v dokladech FAKTICKY CHYBÍ.
A37: ⚠ REFERENCE: e-mail pana Jahnholze uvádí „Projekt 129869“ a referenci „129869 -0-0-00-FRP“, doklady však znějí na 129689 (faktura, packing note, export declaration). Zřejmě překlep v e-mailu – potvrdit.
A39: 6) CELNÍ HODNOTA – ZÁKLAD PRO URČENÍ NUTNO POTVRDIT | B39: K VYJASNĚNÍ
A40: ⚠ Faktura 129689 nese text: „THE VALUE OF THESE GOODS ARE LISTED FOR CUSTOMS PURPOSES ONLY“ a jde o převod mezi dvěma společnostmi skupiny Hitachi Energy (UK → CZ). Nejde tedy zřejmě o prodej. Pokud prodej neproběhl, nelze celní hodnotu určit převodní hodnotou (čl. 70 UCC) a je nutné použít některou z náhradních metod (čl. 74 UCC). Potvrďte s dovozcem, zda je zboží fakturováno a placeno, nebo jde o bezplatný převod.
A41: ⚠ PŘEPRAVNÉ: Purchase Order 4502372958 ze dne 19.08.2026 je objednávka PŘEPRAVY u DSV Road Ltd – „2x pallets with small goods“ za 487,10 GBP (Terms of Delivery DAP Stone, měna GBP). Nejde o fakturu za zboží.
A42: ➤ Nutno vyjasnit, zda je těchto 487,10 GBP již obsaženo v částce 56 962,01 GBP. Při dodací podmínce CPT Trutnov má přepravu hradit prodávající, a je-li fakturována zvlášť, je nutné náklady až po místo vstupu do EU k celní hodnotě PŘIČÍST (čl. 71 UCC); náklady po vstupu do EU se naopak odečítají, jsou-li vykázány odděleně.
A43: ⚠ NESROVNALOST: pokyn k odbavení uvádí „TUZ úsek: 22 000,- CZK“ (tuzemský úsek), což je zhruba 780 GBP – tedy VÍCE než celkové přepravné 487,10 GBP podle PO 4502372958 za celou trasu. Tyto dva údaje si odporují; před výpočtem celní hodnoty je nutné je sjednotit.
A45: Fakturovaná hodnota: 56 962,01 GBP. Dodací podmínka CPT Trutnov, Česká republika – přeprava až do místa určení je součástí ceny.
A46: V pokynu k odbavení je uvedeno: „TUZ úsek: 22 000,- CZK“ (tuzemský úsek přepravy). Náklady na přepravu po vstupu zboží na celní území EU lze z celní hodnoty odečíst, jsou-li vykázány odděleně – rozdělení a uplatnění je na vás, do souhrnu jsem je nezapočítal.
A47: Obchodní sleva: v dokladech není uvedena žádná sleva, proporcionální rozpuštění slevy se tedy neprovádělo.
...
